Workbook

Sheet Composition
A2: =SUM(B3:D12) -> 1.7939574e+08 | B2: Developed | C2: Emerging Markets | D2: Frontier Markets | E2: Developed | F2: Emerging Markets | G2: Frontier Markets | H2: Developed | I2: Emerging Markets | J2: Frontier Markets | P2: =Bonds!BP107 -> Industry | Q2: =Bonds!BQ107 -> Market Value | R2: =Bonds!BR107 -> % | T2: =Bonds!BT107 -> Country | U2: =Bonds!BU107 -> Market Value | V2: =Bonds!BV107 -> % | X2: =Bonds!BX107 -> Country | Y2: =Bonds!BY107 -> Government | Z2: =Bonds!BZ107 -> AT1 | AA2: =Bonds!CA107 -> Oil and Gas Extraction and Refining | AB2: =Bonds!CB107 -> Banks | AC2: =Bonds!CC107 -> Power | AD2: =Bonds!CD107 -> Chemical and petrochemical industry | AE2: =Bonds!CE107 -> Non-ferrous metals | AF2: =Bonds!CF107 -> Other
A3: Bonds | B3: 34561291 | C3: 33032532 | D3: 4161889.2 | E3: =B3/$A$2 -> 0.19265392 | F3: =C3/$A$2 -> 0.18413221 | G3: =D3/$A$2 -> 0.023199488 | H3: =B3/SUM($B3:$D3) -> 0.48165212 | I3: =C3/SUM($B3:$D3) -> 0.46034707 | J3: =D3/SUM($B3:$D3) -> 0.058000807 | P3: =Bonds!BP108 -> Government | Q3: =Bonds!BQ108 -> 16365970 | R3: =Bonds!BR108 -> 0.22814422 | T3: =Bonds!BT108 -> Brazil | U3: =Bonds!BU108 -> 8799972.8 | V3: =Bonds!BV108 -> 0.12267301 | X3: =Bonds!BX108 -> Brazil | Y3: =Bonds!BY108 -> 0.025547867 | Z3: =Bonds!BZ108 -> 0 | AA3: =Bonds!CA108 -> 0.060261318 | AB3: =Bonds!CB108 -> 0 | AC3: =Bonds!CC108 -> 0.0057604761 | AD3: =Bonds!CD108 -> 0 | AE3: =Bonds!CE108 -> 0 | AF3: =Bonds!CF108 -> 0.031103353
A4: Bonds ETFs | B4: 14063941 | C4: 14582344 | D4: 1000000 | E4: =B4/$A$2 -> 0.078396186 | F4: =C4/$A$2 -> 0.081285903 | G4: =D4/$A$2 -> 0.0055742686 | H4: =B4/SUM($B4:$D4) -> 0.47439135 | I4: =C4/SUM($B4:$D4) -> 0.49187761 | J4: =D4/SUM($B4:$D4) -> 0.033731039 | P4: =Bonds!BP109 -> AT1 | Q4: =Bonds!BQ109 -> 10684224 | R4: =Bonds!BR109 -> 0.14893977 | T4: =Bonds!BT109 -> France | U4: =Bonds!BU109 -> 6570155 | V4: =Bonds!BV109 -> 0.091589 | X4: =Bonds!BX109 -> France | Y4: =Bonds!BY109 -> 0 | Z4: =Bonds!BZ109 -> 0.037596984 | AA4: =Bonds!CA109 -> 0 | AB4: =Bonds!CB109 -> 0 | AC4: =Bonds!CC109 -> 0.02395279 | AD4: =Bonds!CD109 -> 0 | AE4: =Bonds!CE109 -> 0 | AF4: =Bonds!CF109 -> 0.030039226
A5: Private Credit | B5: =9770768.704733-1484693 -> 8286075.7 | E5: =B5/$A$2 -> 0.046188811 | F5: =C5/$A$2 -> 0 | G5: =D5/$A$2 -> 0 | H5: =B5/SUM($B5:$D5) -> 1 | I5: =C5/SUM($B5:$D5) -> 0 | J5: =D5/SUM($B5:$D5) -> 0 | P5: =Bonds!BP110 -> Oil and Gas Extraction and Refining | Q5: =Bonds!BQ110 -> 9318956.9 | R5: =Bonds!BR110 -> 0.12990773 | T5: =Bonds!BT110 -> Mexico | U5: =Bonds!BU110 -> 6454864.9 | V5: =Bonds!BV110 -> 0.089981838 | X5: =Bonds!BX110 -> Mexico | Y5: =Bonds!BY110 -> 0.066445955 | Z5: =Bonds!BZ110 -> 0 | AA5: =Bonds!CA110 -> 0.012659013 | AB5: =Bonds!CB110 -> 0 | AC5: =Bonds!CC110 -> 0.01087687 | AD5: =Bonds!CD110 -> 0 | AE5: =Bonds!CE110 -> 0 | AF5: =Bonds!CF110 -> 0
A6: Equity | B6: 9121276.6 | C6: 1411825.5 | E6: =B6/$A$2 -> 0.050844445 | F6: =C6/$A$2 -> 0.0078698944 | G6: =D6/$A$2 -> 0 | H6: =B6/SUM($B6:$D6) -> 0.86596299 | I6: =C6/SUM($B6:$D6) -> 0.13403701 | J6: =D6/SUM($B6:$D6) -> 0 | P6: =Bonds!BP111 -> Banks | Q6: =Bonds!BQ111 -> 8751754.5 | R6: =Bonds!BR111 -> 0.12200084 | T6: =Bonds!BT111 -> USA | U6: =Bonds!BU111 -> 7734546 | V6: =Bonds!BV111 -> 0.10782079 | X6: =Bonds!BX111 -> USA | Y6: =Bonds!BY111 -> 0.02508378 | Z6: =Bonds!BZ111 -> 0 | AA6: =Bonds!CA111 -> 0 | AB6: =Bonds!CB111 -> 0.027313387 | AC6: =Bonds!CC111 -> 0 | AD6: =Bonds!CD111 -> 0.0052281002 | AE6: =Bonds!CE111 -> 0 | AF6: =Bonds!CF111 -> 0.050195527
A7: Equity ETF | B7: 9194626 | C7: 4072892.6 | E7: =B7/$A$2 -> 0.051253314 | F7: =C7/$A$2 -> 0.022703397 | G7: =D7/$A$2 -> 0 | H7: =B7/SUM($B7:$D7) -> 0.69301776 | I7: =C7/SUM($B7:$D7) -> 0.30698224 | J7: =D7/SUM($B7:$D7) -> 0 | P7: =Bonds!BP112 -> Power | Q7: =Bonds!BQ112 -> 3942420.6 | R7: =Bonds!BR112 -> 0.054957967 | T7: =Bonds!BT112 -> United Kingdom | U7: =Bonds!BU112 -> 6054139.9 | V7: =Bonds!BV112 -> 0.084395667 | X7: =Bonds!BX112 -> United Kingdom | Y7: =Bonds!BY112 -> 0 | Z7: =Bonds!BZ112 -> 0.071513246 | AA7: =Bonds!CA112 -> 0 | AB7: =Bonds!CB112 -> 0.012882422 | AC7: =Bonds!CC112 -> 0 | AD7: =Bonds!CD112 -> 0 | AE7: =Bonds!CE112 -> 0 | AF7: =Bonds!CF112 -> 0
A8: Option | B8: 333276 | C8: 0 | E8: =B8/$A$2 -> 0.0018577699 | F8: =C8/$A$2 -> 0 | G8: =D8/$A$2 -> 0 | H8: =B8/SUM($B8:$D8) -> 1 | I8: =C8/SUM($B8:$D8) -> 0 | J8: =D8/SUM($B8:$D8) -> 0 | P8: =Bonds!BP113 -> Chemical and petrochemical industry | Q8: =Bonds!BQ113 -> 4080698.2 | R8: =Bonds!BR113 -> 0.056885579 | T8: =Bonds!BT113 -> Turkey | U8: =Bonds!BU113 -> 4337997.1 | V8: =Bonds!BV113 -> 0.060472366 | X8: =Bonds!BX113 -> Turkey | Y8: =Bonds!BY113 -> 0.039671977 | Z8: =Bonds!BZ113 -> 0 | AA8: =Bonds!CA113 -> 0 | AB8: =Bonds!CB113 -> 0 | AC8: =Bonds!CC113 -> 0 | AD8: =Bonds!CD113 -> 0 | AE8: =Bonds!CE113 -> 0 | AF8: =Bonds!CF113 -> 0.020800389
A9: JPM Modules | B9: ='JPM - DP (3R)'!W5 -> 13293212 | E9: =B9/$A$2 -> 0.074099934 | F9: =C9/$A$2 -> 0 | G9: =D9/$A$2 -> 0 | P9: =Bonds!BP114 -> Non-ferrous metals | Q9: =Bonds!BQ114 -> 3728370.1 | R9: =Bonds!BR114 -> 0.051974069 | T9: =Bonds!BT114 -> Netherlands | U9: =Bonds!BU114 -> 3904314.1 | V9: =Bonds!BV114 -> 0.054426757 | X9: =Bonds!BX114 -> Netherlands | Y9: =Bonds!BY114 -> 0 | Z9: =Bonds!BZ114 -> 0 | AA9: =Bonds!CA114 -> 0 | AB9: =Bonds!CB114 -> 0.054426757 | AC9: =Bonds!CC114 -> 0 | AD9: =Bonds!CD114 -> 0 | AE9: =Bonds!CE114 -> 0 | AF9: =Bonds!CF114 -> 0
A10: Alternative Assets | B10: ='Alternative assets'!J20 -> 0 | C10: ='Alternative assets'!J21 -> 0 | E10: =B10/$A$2 -> 0 | F10: =C10/$A$2 -> 0 | G10: =D10/$A$2 -> 0 | H10: =IFERROR(B10/SUM($B10:$D10),0) -> 0 | I10: =IFERROR(C10/SUM($B10:$D10),0) -> 0 | J10: =IFERROR(D10/SUM($B10:$D10),0) -> 0 | P10: =Bonds!BP115 -> Insurance and Reinsurance | Q10: =Bonds!BQ115 -> 1870799.9 | R10: =Bonds!BR115 -> 0.026079247 | T10: =Bonds!BT115 -> India | U10: =Bonds!BU115 -> 3817299.5 | V10: =Bonds!BV115 -> 0.053213759 | X10: =Bonds!BX115 -> India | Y10: =Bonds!BY115 -> 0 | Z10: =Bonds!BZ115 -> 0 | AA10: =Bonds!CA115 -> 0 | AB10: =Bonds!CB115 -> 0 | AC10: =Bonds!CC115 -> 0 | AD10: =Bonds!CD115 -> 0 | AE10: =Bonds!CE115 -> 0.043237562 | AF10: =Bonds!CF115 -> 0.0099761968
A11: Cash | B11: 10854064 | E11: =B11/$A$2 -> 0.06050347 | F11: =C11/$A$2 -> 0 | G11: =D11/$A$2 -> 0 | H11: =B11/SUM($B11:$D11) -> 1 | I11: =C11/SUM($B11:$D11) -> 0 | J11: =D11/SUM($B11:$D11) -> 0 | P11: =Bonds!BP116 -> Food and Beverage Production | Q11: =Bonds!BQ116 -> 1365730.6 | R11: =Bonds!BR116 -> 0.0190385 | T11: =Bonds!BT116 -> Colombia | U11: =Bonds!BU116 -> 3641957.5 | V11: =Bonds!BV116 -> 0.050769464 | X11: =Bonds!BX116 -> Colombia | Y11: =Bonds!BY116 -> 0.021952752 | Z11: =Bonds!BZ116 -> 0 | AA11: =Bonds!CA116 -> 0.020430057 | AB11: =Bonds!CB116 -> 0 | AC11: =Bonds!CC116 -> 0 | AD11: =Bonds!CD116 -> 0 | AE11: =Bonds!CE116 -> 0 | AF11: =Bonds!CF116 -> 0.0083866548
A12: RE proceeds 2026 | B12: 21426488 | E12: =B12/$A$2 -> 0.119437 | F12: =C12/$A$2 -> 0 | G12: =D12/$A$2 -> 0 | H12: =B12/SUM($B12:$D12) -> 1 | I12: =C12/SUM($B12:$D12) -> 0 | J12: =D12/SUM($B12:$D12) -> 0 | P12: =Bonds!BP117 -> Other Financial Institutions | Q12: =Bonds!BQ117 -> 1310781.8 | R12: =Bonds!BR117 -> 0.018272505 | T12: =Bonds!BT117 -> Israel | U12: =Bonds!BU117 -> 3178434.4 | V12: =Bonds!BV117 -> 0.044307879 | X12: =Bonds!BX117 -> Israel | Y12: =Bonds!BY117 -> 0.0084761738 | Z12: =Bonds!BZ117 -> 0 | AA12: =Bonds!CA117 -> 0.0087005407 | AB12: =Bonds!CB117 -> 0 | AC12: =Bonds!CC117 -> 0 | AD12: =Bonds!CD117 -> 0.014751592 | AE12: =Bonds!CE117 -> 0 | AF12: =Bonds!CF117 -> 0.012379573
P13: =Bonds!BP118 -> Ferrous metals | Q13: =Bonds!BQ118 -> 1289932.1 | R13: =Bonds!BR118 -> 0.017981857 | T13: =Bonds!BT118 -> Japan | U13: =Bonds!BU118 -> 2656651.1 | V13: =Bonds!BV118 -> 0.037034137 | X13: =Bonds!BX118 -> Japan | Y13: =Bonds!BY118 -> 0 | Z13: =Bonds!BZ118 -> 0 | AA13: =Bonds!CA118 -> 0 | AB13: =Bonds!CB118 -> 0.027378277 | AC13: =Bonds!CC118 -> 0 | AD13: =Bonds!CD118 -> 0 | AE13: =Bonds!CE118 -> 0 | AF13: =Bonds!CF118 -> 0.0096558597
A14: Total | B14: =SUM(B3:B12) -> 1.2113425e+08 | C14: =SUM(C3:C12) -> 53099595 | D14: =SUM(D3:D12) -> 5161889.2 | E14: =SUM(E3:E12) -> 0.67523484 | F14: =SUM(F3:F12) -> 0.2959914 | G14: =SUM(G3:G12) -> 0.028773757 | P14: =Bonds!BP119 -> Communication Services | Q14: =Bonds!BQ119 -> 1067662.5 | R14: =Bonds!BR119 -> 0.014883384 | T14: =Bonds!BT119 -> Austria | U14: =Bonds!BU119 -> 1810912.9 | V14: =Bonds!BV119 -> 0.025244413 | X14: =Bonds!BX119 -> Austria | Y14: =Bonds!BY119 -> 0 | Z14: =Bonds!BZ119 -> 0.025244413 | AA14: =Bonds!CA119 -> 0 | AB14: =Bonds!CB119 -> 0 | AC14: =Bonds!CC119 -> 0 | AD14: =Bonds!CD119 -> 0 | AE14: =Bonds!CE119 -> 0 | AF14: =Bonds!CF119 -> 0
P15: =Bonds!BP120 -> Air Transportation | Q15: =Bonds!BQ120 -> 707432.99 | R15: =Bonds!BR120 -> 0.0098617278 | T15: =Bonds!BT120 -> South Africa | U15: =Bonds!BU120 -> 2274733.8 | V15: =Bonds!BV120 -> 0.031710149 | X15: =Bonds!BX120 -> South Africa | Y15: =Bonds!BY120 -> 0.0090548995 | Z15: =Bonds!BZ120 -> 0 | AA15: =Bonds!CA120 -> 0 | AB15: =Bonds!CB120 -> 0 | AC15: =Bonds!CC120 -> 0 | AD15: =Bonds!CD120 -> 0.0098287099 | AE15: =Bonds!CE120 -> 0 | AF15: =Bonds!CF120 -> 0.01282654
P16: =Bonds!BP121 -> Holding Companies | Q16: =Bonds!BQ121 -> 920114.38 | R16: =Bonds!BR121 -> 0.01282654 | T16: =Bonds!BT121 -> Morocco | U16: =Bonds!BU121 -> 1942386.7 | V16: =Bonds!BV121 -> 0.027077177 | X16: =Bonds!BX121 -> Morocco | Y16: =Bonds!BY121 -> 0 | Z16: =Bonds!BZ121 -> 0 | AA16: =Bonds!CA121 -> 0 | AB16: =Bonds!CB121 -> 0 | AC16: =Bonds!CC121 -> 0 | AD16: =Bonds!CD121 -> 0.027077177 | AE16: =Bonds!CE121 -> 0 | AF16: =Bonds!CF121 -> 0
P17: =Bonds!BP122 -> Media | Q17: =Bonds!BQ122 -> 857284.4 | R17: =Bonds!BR122 -> 0.01195068 | T17: =Bonds!BT122 -> Chile | U17: =Bonds!BU122 -> 1334148 | V17: =Bonds!BV122 -> 0.018598234 | X17: =Bonds!BX122 -> Chile | Y17: =Bonds!BY122 -> 0 | Z17: =Bonds!BZ122 -> 0 | AA17: =Bonds!CA122 -> 0 | AB17: =Bonds!CB122 -> 0 | AC17: =Bonds!CC122 -> 0 | AD17: =Bonds!CD122 -> 0 | AE17: =Bonds!CE122 -> 0.0087365063 | AF17: =Bonds!CF122 -> 0.0098617278
P18: =Bonds!BP123 -> Transportation Support Activities | Q18: =Bonds!BQ123 -> 715644.44 | R18: =Bonds!BR123 -> 0.0099761968 | T18: =Bonds!BT123 -> Romania | U18: =Bonds!BU123 -> 1442145.3 | V18: =Bonds!BV123 -> 0.020103733 | X18: =Bonds!BX123 -> Romania | Y18: =Bonds!BY123 -> 0.020103733 | Z18: =Bonds!BZ123 -> 0 | AA18: =Bonds!CA123 -> 0 | AB18: =Bonds!CB123 -> 0 | AC18: =Bonds!CC123 -> 0 | AD18: =Bonds!CD123 -> 0 | AE18: =Bonds!CE123 -> 0 | AF18: =Bonds!CF123 -> 0
P19: =Bonds!BP124 -> Online Retail | Q19: =Bonds!BQ124 -> 692665 | R19: =Bonds!BR124 -> 0.0096558597 | T19: =Bonds!BT124 -> Kazakhstan | U19: =Bonds!BU124 -> 1393365.6 | V19: =Bonds!BV124 -> 0.019423737 | X19: =Bonds!BX124 -> Kazakhstan | Y19: =Bonds!BY124 -> 0 | Z19: =Bonds!BZ124 -> 0 | AA19: =Bonds!CA124 -> 0.019423737 | AB19: =Bonds!CB124 -> 0 | AC19: =Bonds!CC124 -> 0 | AD19: =Bonds!CD124 -> 0 | AE19: =Bonds!CE124 -> 0 | AF19: =Bonds!CF124 -> 0
P20: =Bonds!BP125 -> Motor Vehicle Production | Q20: =Bonds!BQ125 -> 596426.67 | R20: =Bonds!BR125 -> 0.0083142821 | T20: =Bonds!BT125 -> Switzerland | U20: =Bonds!BU125 -> 1046267.2 | V20: =Bonds!BV125 -> 0.014585131 | X20: =Bonds!BX125 -> Switzerland | Y20: =Bonds!BY125 -> 0 | Z20: =Bonds!BZ125 -> 0.014585131 | AA20: =Bonds!CA125 -> 0 | AB20: =Bonds!CB125 -> 0 | AC20: =Bonds!CC125 -> 0 | AD20: =Bonds!CD125 -> 0 | AE20: =Bonds!CE125 -> 0 | AF20: =Bonds!CF125 -> 0
P21: =Bonds!BP126 -> Leasing and Rental | Q21: =Bonds!BQ126 -> 566155.57 | R21: =Bonds!BR126 -> 0.0078922982 | T21: =Bonds!BT126 -> Panama | U21: =Bonds!BU126 -> 846983.09 | V21: =Bonds!BV126 -> 0.011807078 | X21: =Bonds!BX126 -> Panama | Y21: =Bonds!BY126 -> 0.011807078 | Z21: =Bonds!BZ126 -> 0 | AA21: =Bonds!CA126 -> 0 | AB21: =Bonds!CB126 -> 0 | AC21: =Bonds!CC126 -> 0 | AD21: =Bonds!CD126 -> 0 | AE21: =Bonds!CE126 -> 0 | AF21: =Bonds!CF126 -> 0
P22: =Bonds!BP127 -> Energy | Q22: =Bonds!BQ127 -> 601618.33 | R22: =Bonds!BR127 -> 0.0083866548 | T22: =Bonds!BT127 -> Italy | U22: =Bonds!BU127 -> 542380.34 | V22: =Bonds!BV127 -> 0.0075608678 | X22: =Bonds!BX127 -> Italy | Y22: =Bonds!BY127 -> 0 | Z22: =Bonds!BZ127 -> 0 | AA22: =Bonds!CA127 -> 0 | AB22: =Bonds!CB127 -> 0 | AC22: =Bonds!CC127 -> 0.0075608678 | AD22: =Bonds!CD127 -> 0 | AE22: =Bonds!CE127 -> 0 | AF22: =Bonds!CF127 -> 0
P23: =Bonds!BP128 -> Fertilizers | Q23: =Bonds!BQ128 -> 440108.74 | R23: =Bonds!BR128 -> 0.0061351854 | T23: =Bonds!BT128 -> Denmark | U23: =Bonds!BU128 -> 488298.86 | V23: =Bonds!BV128 -> 0.0068069633 | X23: =Bonds!BX128 -> Denmark | Y23: =Bonds!BY128 -> 0 | Z23: =Bonds!BZ128 -> 0 | AA23: =Bonds!CA128 -> 0 | AB23: =Bonds!CB128 -> 0 | AC23: =Bonds!CC128 -> 0.0068069633 | AD23: =Bonds!CD128 -> 0 | AE23: =Bonds!CE128 -> 0 | AF23: =Bonds!CF128 -> 0
P24: =Bonds!BP129 -> Mining: Other | Q24: =Bonds!BQ129 -> 418186.67 | R24: =Bonds!BR129 -> 0.0058295883 | T24: =Bonds!BT129 -> Hungary | U24: =Bonds!BU129 -> 440108.74 | V24: =Bonds!BV129 -> 0.0061351854 | X24: =Bonds!BX129 -> Hungary | Y24: =Bonds!BY129 -> 0 | Z24: =Bonds!BZ129 -> 0 | AA24: =Bonds!CA129 -> 0 | AB24: =Bonds!CB129 -> 0 | AC24: =Bonds!CC129 -> 0 | AD24: =Bonds!CD129 -> 0 | AE24: =Bonds!CE129 -> 0 | AF24: =Bonds!CF129 -> 0.0061351854
P25: =Bonds!BP130 -> Technology | Q25: =Bonds!BQ130 -> 801208.72 | R25: =Bonds!BR130 -> 0.011168976 | T25: =Bonds!BT130 -> Canada | U25: =Bonds!BU130 -> 218691.11 | V25: =Bonds!BV130 -> 0.0030485887 | X25: =Bonds!BX130 -> Canada | Y25: =Bonds!BY130 -> 0 | Z25: =Bonds!BZ130 -> 0 | AA25: =Bonds!CA130 -> 0.0030485887 | AB25: =Bonds!CB130 -> 0 | AC25: =Bonds!CC130 -> 0 | AD25: =Bonds!CD130 -> 0 | AE25: =Bonds!CE130 -> 0 | AF25: =Bonds!CF130 -> 0
P26: =Bonds!BP131 -> Semiconductors | Q26: =Bonds!BQ131 -> 356980 | R26: =Bonds!BR131 -> 0.0049763577 | T26: =Bonds!BT131 -> Indonesia | U26: =Bonds!BU131 -> 418186.67 | V26: =Bonds!BV131 -> 0.0058295883 | X26: =Bonds!BX131 -> Indonesia | Y26: =Bonds!BY131 -> 0 | Z26: =Bonds!BZ131 -> 0 | AA26: =Bonds!CA131 -> 0 | AB26: =Bonds!CB131 -> 0 | AC26: =Bonds!CC131 -> 0 | AD26: =Bonds!CD131 -> 0 | AE26: =Bonds!CE131 -> 0 | AF26: =Bonds!CF131 -> 0.0058295883
P27: =Bonds!BP132 -> Utilities | Q27: =Bonds!BQ132 -> 284069.89 | R27: =Bonds!BR132 -> 0.0039599792 | T27: =Bonds!BT132 -> Australia | U27: =Bonds!BU132 -> 386256.67 | V27: =Bonds!BV132 -> 0.005384479 | X27: =Bonds!BX132 -> Australia | Y27: =Bonds!BY132 -> 0 | Z27: =Bonds!BZ132 -> 0 | AA27: =Bonds!CA132 -> 0.005384479 | AB27: =Bonds!CB132 -> 0 | AC27: =Bonds!CC132 -> 0 | AD27: =Bonds!CD132 -> 0 | AE27: =Bonds!CE132 -> 0 | AF27: =Bonds!CF132 -> 0
T33: =Bonds!BT138 -> Market | U33: =Bonds!BU138 -> Market Value | V33: =Bonds!BV138 -> % | X33: =Bonds!BX138 -> Market | Y33: =Bonds!BY138 -> Government | Z33: =Bonds!BZ138 -> AT1 | AA33: =Bonds!CA138 -> Oil and Gas Extraction and Refining | AB33: =Bonds!CB138 -> Banks | AC33: =Bonds!CC138 -> Power | AD33: =Bonds!CD138 -> Chemical and petrochemical industry | AE33: =Bonds!CE138 -> Non-ferrous metals | AF33: =Bonds!CF138 -> Other
T34: =Bonds!BT139 -> Developed | U34: =Bonds!BU139 -> 34591048 | V34: =Bonds!BV139 -> 0.48220468 | X34: =Bonds!BX139 -> Emerging Markets | Y34: =Bonds!BY139 -> 0.18277718 | Z34: =Bonds!BZ139 -> 0 | AA34: =Bonds!CA139 -> 0.093350388 | AB34: =Bonds!CB139 -> 0 | AC34: =Bonds!CC139 -> 0.016637346 | AD34: =Bonds!CD139 -> 0.0098287099 | AE34: =Bonds!CE139 -> 0.051974069 | AF34: =Bonds!CF139 -> 0.12763698
T35: =Bonds!BT140 -> Emerging Markets | U35: =Bonds!BU140 -> 32961414 | V35: =Bonds!BV140 -> 0.45948733 | X35: =Bonds!BX140 -> Developed | Y35: =Bonds!BY140 -> 0.033559954 | Z35: =Bonds!BZ140 -> 0.14893977 | AA35: =Bonds!CA140 -> 0.017133608 | AB35: =Bonds!CB140 -> 0.12200084 | AC35: =Bonds!CC140 -> 0.038320621 | AD35: =Bonds!CD140 -> 0.019979692 | AE35: =Bonds!CE140 -> 0 | AF35: =Bonds!CF140 -> 0.079552839
T36: =Bonds!BT141 -> Frontier Markets | U36: =Bonds!BU141 -> 4182735.4 | V36: =Bonds!BV141 -> 0.058307993 | X36: =Bonds!BX141 -> Frontier Markets | Y36: =Bonds!BY141 -> 0.011807078 | Z36: =Bonds!BZ141 -> 0 | AA36: =Bonds!CA141 -> 0.019423737 | AB36: =Bonds!CB141 -> 0 | AC36: =Bonds!CC141 -> 0 | AD36: =Bonds!CD141 -> 0.027077177 | AE36: =Bonds!CE141 -> 0 | AF36: =Bonds!CF141 -> 0
T38: =Bonds!BT143 -> Market | U38: =Bonds!BU143 -> Market Value | V38: =Bonds!BV143 -> %
T39: =Bonds!BT144 -> USA | U39: =Bonds!BU144 -> 7734546 | V39: =Bonds!BV144 -> 0.10782079
T40: =Bonds!BT145 -> United Kingdom | U40: =Bonds!BU145 -> 6054139.9 | V40: =Bonds!BV145 -> 0.084395667
T41: =Bonds!BT146 -> Europe | U41: =Bonds!BU146 -> 12732695 | V41: =Bonds!BV146 -> 0.17749578
T42: =Bonds!BT147 -> Japan | U42: =Bonds!BU147 -> 2656651.1 | V42: =Bonds!BV147 -> 0.037034137
T43: =Bonds!BT148 -> Israel | U43: =Bonds!BU148 -> 3178434.4 | V43: =Bonds!BV148 -> 0.044307879
T44: =Bonds!BT149 -> Other DM | U44: =Bonds!BU149 -> 604947.78 | V44: =Bonds!BV149 -> 0.0084330677
T45: =Bonds!BT150 -> Brazil | U45: =Bonds!BU150 -> 8799972.8 | V45: =Bonds!BV150 -> 0.12267301
T46: =Bonds!BT151 -> Mexico | U46: =Bonds!BU151 -> 6454864.9 | V46: =Bonds!BV151 -> 0.089981838
T47: =Bonds!BT152 -> Turkey | U47: =Bonds!BU152 -> 4337997.1 | V47: =Bonds!BV152 -> 0.060472366
...

Sheet Results
B2: All-portfolio | S2: Portfolio Loans, 2025
B3: Currency | C3: Weights | D3: AW coupon (CCY) | E3: AW Current yield (CCY) | F3: Total inflows (CCY) | G3: Total inflows (USD) | H3: Total MV of positions, CCY | I3: Total MV of positions (USD) | S3: CCY | T3: Cost of debt, 2025 | U3: Curent debt CCY | V3: Current Debt USD | W3: Annual interest, CCY | X3: Annual interest, USD | Y3: Total coupon, CCY
B4: USD | C4: =I4/$I$11 -> #VALUE! | D4: =IFERROR(( SUMIFS(T_Bonds[Coupon in Loc.Curr],T_Bonds[Risk CCY],Results!$B4)+ SUMIFS(T_bETFs[Coupon in CCY],T_bETFs[Risk CCY],$B4)+ SUMIFS(T_deposits[Coupon in Loc.Curr],T_deposits[Risk CCY],$B4)+ SUMIFS(T_Eq[Dividend in Loc.Curr],T_Eq[Risk CCY],B4))/ (SUMIFS(T_Bonds[Quantity],T_Bonds[Risk CCY],$B4)+ SUMIFS(T_bETFs[Market Value, CCY],T_bETFs[Risk CCY],B4)+ SUMIFS(T_deposits[Quantity],T_deposits[Risk CCY],B4)+ SUMIFS(T_Eq[Market value, CCY],T_Eq[Risk CCY],B4)),"") | E4: =IFERROR((SUMIFS(T_Bonds[Coupon in Loc.Curr],T_Bonds[Risk CCY],Results!$B4)+ SUMIFS(T_bETFs[Coupon in CCY],T_bETFs[Risk CCY],$B4)+ SUMIFS(T_deposits[Coupon in Loc.Curr],T_deposits[Risk CCY],$B4)+ SUMIFS(T_Eq[Dividend in Loc.Curr],T_Eq[Risk CCY],B4))/ (SUMIFS(T_Bonds[Cost value],T_Bonds[Risk CCY],$B4)+ SUMIFS(T_bETFs[Market Value, CCY],T_bETFs[Risk CCY],$B4)+ SUMIFS(T_deposits[Quantity],T_deposits[Risk CCY],$B4)+ SUMIFS(T_Eq[Market value, CCY],T_Eq[Risk CCY],B4)),"") | F4: =IFERROR( SUMIFS(T_Bonds[Coupon in Loc.Curr],T_Bonds[Risk CCY],Results!$B4)+ SUMIFS(T_bETFs[Coupon in CCY],T_bETFs[Risk CCY],$B4)+ SUMIFS(T_deposits[Coupon in Loc.Curr],T_deposits[Risk CCY],$B4)+ SUMIFS(T_Eq[Dividend in Loc.Curr],T_Eq[Risk CCY],B4)+ SUMIFS('Real Estate'!X:X,'Real Estate'!D:D,B4),"") | G4: =IFERROR( SUMIFS(T_Bonds[Coupon in USD],T_Bonds[Risk CCY],Results!$B4)+ SUMIFS(T_bETFs[Coupon in USD],T_bETFs[Risk CCY],$B4)+ SUMIFS(T_deposits[Coupon in USD],T_deposits[Risk CCY],$B4)+ SUMIFS(T_Eq[Dividend in USD],T_Eq[Risk CCY],B4)+ SUMIFS('Real Estate'!Y:Y,'Real Estate'!D:D,B4),"") | H4: =IFERROR((SUMIFS(T_Bonds[Full MV in CCY],T_Bonds[Risk CCY],Results!$B4)+ SUMIFS(T_bETFs[Market value in CCY],T_bETFs[Risk CCY],$B4)+ SUMIFS(T_deposits[Market value in USD],T_deposits[Risk CCY],$B4)+ SUMIFS(T_Eq[Market value, CCY],T_Eq[Risk CCY],$B4)+ SUMIFS(T_AI[Market value in CCY],T_AI[Risk CCY],$B4)+ SUMIFS(Cash!F:F,Cash!E:E,$B4))+ SUMIFS('Real Estate'!$G:$G,'Real Estate'!$D:$D,B4)+ SUMIFS('JPM - DP (3R)'!$F:$F,'JPM - DP (3R)'!$C:$C,B4),"") | I4: =IFERROR((SUMIFS(T_Bonds[Full MV in USD],T_Bonds[Risk CCY],Results!$B4)+ SUMIFS(T_bETFs[Market value in USD],T_bETFs[Risk CCY],$B4)+ SUMIFS(T_deposits[Market value in USD],T_deposits[Risk CCY],$B4)+ SUMIFS(T_Eq[Market value, USD],T_Eq[Risk CCY],$B4)+ SUMIFS(T_AI[Market value in USD],T_AI[Risk CCY],$B4)+ SUMIFS(Cash!H:H,Cash!E:E,$B4)+ SUMIFS('Real Estate'!$F:$F,'Real Estate'!$D:$D,B4)+ SUMIFS('JPM - DP (3R)'!$J:$J,'JPM - DP (3R)'!$C:$C,Results!B4)),"") | S4: USD | T4: {=IFERROR(SUMPRODUCT(Loans!D:D,Loans!F:F,IF(Loans!C:C=LTV!F5,1,0))/SUMIFS(Loans!D:D,Loans!C:C,LTV!F5),0)} -> 0.044834337 | U4: =-SUMIFS(Loans!D:D,Loans!C:C,LTV!F5) -> 210492.39 | V4: =-SUMIFS(Loans!G:G,Loans!C:C,LTV!F5) -> 210492.39 | W4: =U4*T4 -> 9437.2868 | X4: =INDEX('Tech list'!$A$2:$C$8,MATCH(S4,'Tech list'!$A$2:$A$8,0),3)*W4 -> 9437.2868 | Y4: =Results!F4
B5: GBP | C5: =I5/$I$11 -> 0.91907904 | D5: =IFERROR((SUMIFS(T_Bonds[Coupon in Loc.Curr],T_Bonds[Risk CCY],Results!$B5)+SUMIFS(T_bETFs[Coupon in CCY],T_bETFs[Risk CCY],$B5)+SUMIFS(T_deposits[Coupon in Loc.Curr],T_deposits[Risk CCY],$B5)+SUMIFS(T_Eq[Dividend in Loc.Curr],T_Eq[Risk CCY],B5))/(SUMIFS(T_Bonds[Quantity],T_Bonds[Risk CCY],$B5)+SUMIFS(T_bETFs[Market Value, CCY],T_bETFs[Risk CCY],B5)+SUMIFS(T_deposits[Quantity],T_deposits[Risk CCY],B5)+SUMIFS(T_Eq[Market value, CCY],T_Eq[Risk CCY],B5)),"") -> 0.063007408 | E5: =IFERROR((SUMIFS(T_Bonds[Coupon in Loc.Curr],T_Bonds[Risk CCY],Results!$B5)+SUMIFS(T_bETFs[Coupon in CCY],T_bETFs[Risk CCY],$B5)+SUMIFS(T_deposits[Coupon in Loc.Curr],T_deposits[Risk CCY],$B5)+SUMIFS(T_Eq[Dividend in Loc.Curr],T_Eq[Risk CCY],B5))/ (SUMIFS(T_Bonds[Cost value],T_Bonds[Risk CCY],$B5)+SUMIFS(T_bETFs[Market Value, CCY],T_bETFs[Risk CCY],$B5)+SUMIFS(T_deposits[Quantity],T_deposits[Risk CCY],$B5)+SUMIFS(T_Eq[Market value, CCY],T_Eq[Risk CCY],B5)),"") -> 0.069515964 | F5: =IFERROR( SUMIFS(T_Bonds[Coupon in Loc.Curr],T_Bonds[Risk CCY],Results!$B5)+ SUMIFS(T_bETFs[Coupon in CCY],T_bETFs[Risk CCY],$B5)+ SUMIFS(T_deposits[Coupon in Loc.Curr],T_deposits[Risk CCY],$B5)+ SUMIFS(T_Eq[Dividend in Loc.Curr],T_Eq[Risk CCY],B5)+ SUMIFS('Real Estate'!X:X,'Real Estate'!D:D,B5),"") -> 1898227.5 | G5: =IFERROR( SUMIFS(T_Bonds[Coupon in USD],T_Bonds[Risk CCY],Results!$B5)+ SUMIFS(T_bETFs[Coupon in USD],T_bETFs[Risk CCY],$B5)+ SUMIFS(T_deposits[Coupon in USD],T_deposits[Risk CCY],$B5)+ SUMIFS(T_Eq[Dividend in USD],T_Eq[Risk CCY],B5)+ SUMIFS('Real Estate'!Y:Y,'Real Estate'!D:D,B5),"") -> 2538689.5 | H5: =IFERROR((SUMIFS(T_Bonds[Full MV in CCY],T_Bonds[Risk CCY],Results!$B5)+ SUMIFS(T_bETFs[Market value in CCY],T_bETFs[Risk CCY],$B5)+ SUMIFS(T_deposits[Market value in USD],T_deposits[Risk CCY],$B5)+ SUMIFS(T_Eq[Market value, CCY],T_Eq[Risk CCY],$B5)+ SUMIFS(T_AI[Market value in CCY],T_AI[Risk CCY],$B5)+ SUMIFS(Cash!F:F,Cash!E:E,$B5))+ SUMIFS('Real Estate'!$G:$G,'Real Estate'!$D:$D,B5)+ SUMIFS('JPM - DP (3R)'!$F:$F,'JPM - DP (3R)'!$C:$C,B5),"") -> 37611397 | I5: =IFERROR((SUMIFS(T_Bonds[Full MV in USD],T_Bonds[Risk CCY],Results!$B5)+ SUMIFS(T_bETFs[Market value in USD],T_bETFs[Risk CCY],$B5)+ SUMIFS(T_deposits[Market value in USD],T_deposits[Risk CCY],$B5)+ SUMIFS(T_Eq[Market value, USD],T_Eq[Risk CCY],$B5)+ SUMIFS(T_AI[Market value in USD],T_AI[Risk CCY],$B5)+ SUMIFS(Cash!H:H,Cash!E:E,$B5)+ SUMIFS('Real Estate'!$F:$F,'Real Estate'!$D:$D,B5)+ SUMIFS('JPM - DP (3R)'!$J:$J,'JPM - DP (3R)'!$C:$C,Results!B5)),"") -> 50301482 | S5: GBP | T5: {=IFERROR(SUMPRODUCT(Loans!D:D,Loans!F:F,IF(Loans!C:C=LTV!F6,1,0))/SUMIFS(Loans!D:D,Loans!C:C,LTV!F6),0)} -> 0.043572191 | U5: =-SUMIFS(Loans!D:D,Loans!C:C,LTV!F6) -> 1707086.5 | V5: =-SUMIFS(Loans!G:G,Loans!C:C,LTV!F6) -> 2283057.5 | W5: =U5*T5 -> 74381.498 | X5: =INDEX('Tech list'!$A$2:$C$8,MATCH(S5,'Tech list'!$A$2:$A$8,0),3)*W5 -> 99477.815 | Y5: =Results!F5 -> 1898227.5
B6: EUR | C6: =I6/$I$11 -> #VALUE! | D6: =IFERROR((SUMIFS(T_Bonds[Coupon in Loc.Curr],T_Bonds[Risk CCY],Results!$B6)+SUMIFS(T_bETFs[Coupon in CCY],T_bETFs[Risk CCY],$B6)+SUMIFS(T_deposits[Coupon in Loc.Curr],T_deposits[Risk CCY],$B6)+SUMIFS(T_Eq[Dividend in Loc.Curr],T_Eq[Risk CCY],B6))/(SUMIFS(T_Bonds[Quantity],T_Bonds[Risk CCY],$B6)+SUMIFS(T_bETFs[Market Value, CCY],T_bETFs[Risk CCY],B6)+SUMIFS(T_deposits[Quantity],T_deposits[Risk CCY],B6)+SUMIFS(T_Eq[Market value, CCY],T_Eq[Risk CCY],B6)),"") | E6: =IFERROR((SUMIFS(T_Bonds[Coupon in Loc.Curr],T_Bonds[Risk CCY],Results!$B6)+SUMIFS(T_bETFs[Coupon in CCY],T_bETFs[Risk CCY],$B6)+SUMIFS(T_deposits[Coupon in Loc.Curr],T_deposits[Risk CCY],$B6)+SUMIFS(T_Eq[Dividend in Loc.Curr],T_Eq[Risk CCY],B6))/ (SUMIFS(T_Bonds[Cost value],T_Bonds[Risk CCY],$B6)+SUMIFS(T_bETFs[Market Value, CCY],T_bETFs[Risk CCY],$B6)+SUMIFS(T_deposits[Quantity],T_deposits[Risk CCY],$B6)+SUMIFS(T_Eq[Market value, CCY],T_Eq[Risk CCY],B6)),"") | F6: =IFERROR( SUMIFS(T_Bonds[Coupon in Loc.Curr],T_Bonds[Risk CCY],Results!$B6)+ SUMIFS(T_bETFs[Coupon in CCY],T_bETFs[Risk CCY],$B6)+ SUMIFS(T_deposits[Coupon in Loc.Curr],T_deposits[Risk CCY],$B6)+ SUMIFS(T_Eq[Dividend in Loc.Curr],T_Eq[Risk CCY],B6)+ SUMIFS('Real Estate'!X:X,'Real Estate'!D:D,B6),"") | G6: =IFERROR( SUMIFS(T_Bonds[Coupon in USD],T_Bonds[Risk CCY],Results!$B6)+ SUMIFS(T_bETFs[Coupon in USD],T_bETFs[Risk CCY],$B6)+ SUMIFS(T_deposits[Coupon in USD],T_deposits[Risk CCY],$B6)+ SUMIFS(T_Eq[Dividend in USD],T_Eq[Risk CCY],B6)+ SUMIFS('Real Estate'!Y:Y,'Real Estate'!D:D,B6),"") | H6: =IFERROR((SUMIFS(T_Bonds[Full MV in CCY],T_Bonds[Risk CCY],Results!$B6)+ SUMIFS(T_bETFs[Market value in CCY],T_bETFs[Risk CCY],$B6)+ SUMIFS(T_deposits[Market value in USD],T_deposits[Risk CCY],$B6)+ SUMIFS(T_Eq[Market value, CCY],T_Eq[Risk CCY],$B6)+ SUMIFS(T_AI[Market value in CCY],T_AI[Risk CCY],$B6)+ SUMIFS(Cash!F:F,Cash!E:E,$B6))+ SUMIFS('Real Estate'!$G:$G,'Real Estate'!$D:$D,B6)+ SUMIFS('JPM - DP (3R)'!$F:$F,'JPM - DP (3R)'!$C:$C,B6),"") | I6: =IFERROR((SUMIFS(T_Bonds[Full MV in USD],T_Bonds[Risk CCY],Results!$B6)+ SUMIFS(T_bETFs[Market value in USD],T_bETFs[Risk CCY],$B6)+ SUMIFS(T_deposits[Market value in USD],T_deposits[Risk CCY],$B6)+ SUMIFS(T_Eq[Market value, USD],T_Eq[Risk CCY],$B6)+ SUMIFS(T_AI[Market value in USD],T_AI[Risk CCY],$B6)+ SUMIFS(Cash!H:H,Cash!E:E,$B6)+ SUMIFS('Real Estate'!$F:$F,'Real Estate'!$D:$D,B6)+ SUMIFS('JPM - DP (3R)'!$J:$J,'JPM - DP (3R)'!$C:$C,Results!B6)),"") | S6: EUR | T6: {=IFERROR(SUMPRODUCT(Loans!D:D,Loans!F:F,IF(Loans!C:C=LTV!F7,1,0))/SUMIFS(Loans!D:D,Loans!C:C,LTV!F7),0)} -> 0.025230202 | U6: =-SUMIFS(Loans!D:D,Loans!C:C,LTV!F7) -> 24672588 | V6: =-SUMIFS(Loans!G:G,Loans!C:C,LTV!F7) -> 28548652 | W6: =U6*T6 -> 622494.39 | X6: =INDEX('Tech list'!$A$2:$C$8,MATCH(S6,'Tech list'!$A$2:$A$8,0),3)*W6 -> 720288.25 | Y6: =Results!F6
B7: CAD | C7: =I7/$I$11 -> 0.0091288238 | D7: =IFERROR((SUMIFS(T_Bonds[Coupon in Loc.Curr],T_Bonds[Risk CCY],Results!$B7)+SUMIFS(T_bETFs[Coupon in CCY],T_bETFs[Risk CCY],$B7)+SUMIFS(T_deposits[Coupon in Loc.Curr],T_deposits[Risk CCY],$B7)+SUMIFS(T_Eq[Dividend in Loc.Curr],T_Eq[Risk CCY],B7))/(SUMIFS(T_Bonds[Quantity],T_Bonds[Risk CCY],$B7)+SUMIFS(T_bETFs[Market Value, CCY],T_bETFs[Risk CCY],B7)+SUMIFS(T_deposits[Quantity],T_deposits[Risk CCY],B7)+SUMIFS(T_Eq[Market value, CCY],T_Eq[Risk CCY],B7)),"") -> 0.0011969776 | E7: =IFERROR((SUMIFS(T_Bonds[Coupon in Loc.Curr],T_Bonds[Risk CCY],Results!$B7)+SUMIFS(T_bETFs[Coupon in CCY],T_bETFs[Risk CCY],$B7)+SUMIFS(T_deposits[Coupon in Loc.Curr],T_deposits[Risk CCY],$B7)+SUMIFS(T_Eq[Dividend in Loc.Curr],T_Eq[Risk CCY],B7))/ (SUMIFS(T_Bonds[Cost value],T_Bonds[Risk CCY],$B7)+SUMIFS(T_bETFs[Market Value, CCY],T_bETFs[Risk CCY],$B7)+SUMIFS(T_deposits[Quantity],T_deposits[Risk CCY],$B7)+SUMIFS(T_Eq[Market value, CCY],T_Eq[Risk CCY],B7)),"") -> 0.0011969776 | F7: =IFERROR( SUMIFS(T_Bonds[Coupon in Loc.Curr],T_Bonds[Risk CCY],Results!$B7)+ SUMIFS(T_bETFs[Coupon in CCY],T_bETFs[Risk CCY],$B7)+ SUMIFS(T_deposits[Coupon in Loc.Curr],T_deposits[Risk CCY],$B7)+ SUMIFS(T_Eq[Dividend in Loc.Curr],T_Eq[Risk CCY],B7)+ SUMIFS('Real Estate'!X:X,'Real Estate'!D:D,B7),"") -> 812 | G7: =IFERROR( SUMIFS(T_Bonds[Coupon in USD],T_Bonds[Risk CCY],Results!$B7)+ SUMIFS(T_bETFs[Coupon in USD],T_bETFs[Risk CCY],$B7)+ SUMIFS(T_deposits[Coupon in USD],T_deposits[Risk CCY],$B7)+ SUMIFS(T_Eq[Dividend in USD],T_Eq[Risk CCY],B7)+ SUMIFS('Real Estate'!Y:Y,'Real Estate'!D:D,B7),"") -> 598.038 | H7: =IFERROR((SUMIFS(T_Bonds[Full MV in CCY],T_Bonds[Risk CCY],Results!$B7)+ SUMIFS(T_bETFs[Market value in CCY],T_bETFs[Risk CCY],$B7)+ SUMIFS(T_deposits[Market value in USD],T_deposits[Risk CCY],$B7)+ SUMIFS(T_Eq[Market value, CCY],T_Eq[Risk CCY],$B7)+ SUMIFS(T_AI[Market value in CCY],T_AI[Risk CCY],$B7)+ SUMIFS(Cash!F:F,Cash!E:E,$B7))+ SUMIFS('Real Estate'!$G:$G,'Real Estate'!$D:$D,B7)+ SUMIFS('JPM - DP (3R)'!$F:$F,'JPM - DP (3R)'!$C:$C,B7),"") -> 678375.25 | I7: =IFERROR((SUMIFS(T_Bonds[Full MV in USD],T_Bonds[Risk CCY],Results!$B7)+ SUMIFS(T_bETFs[Market value in USD],T_bETFs[Risk CCY],$B7)+ SUMIFS(T_deposits[Market value in USD],T_deposits[Risk CCY],$B7)+ SUMIFS(T_Eq[Market value, USD],T_Eq[Risk CCY],$B7)+ SUMIFS(T_AI[Market value in USD],T_AI[Risk CCY],$B7)+ SUMIFS(Cash!H:H,Cash!E:E,$B7)+ SUMIFS('Real Estate'!$F:$F,'Real Estate'!$D:$D,B7)+ SUMIFS('JPM - DP (3R)'!$J:$J,'JPM - DP (3R)'!$C:$C,Results!B7)),"") -> 499623.37 | S7: CHF | T7: {=IFERROR(SUMPRODUCT(Loans!D:D,Loans!F:F,IF(Loans!C:C=LTV!F8,1,0))/SUMIFS(Loans!D:D,Loans!C:C,LTV!F8),0)} -> 0.0066570933 | U7: =-SUMIFS(Loans!D:D,Loans!C:C,LTV!F8) -> 13640419 | V7: =-SUMIFS(Loans!G:G,Loans!C:C,LTV!F8) -> 17503386 | W7: =U7*T7 -> 90805.541 | X7: =INDEX('Tech list'!$A$2:$C$8,MATCH(S7,'Tech list'!$A$2:$A$8,0),3)*W7 -> 116521.67 | Y7: 0
B8: BRL | C8: =I8/$I$11 -> 0.043523631 | D8: =IFERROR((SUMIFS(T_Bonds[Coupon in Loc.Curr],T_Bonds[Risk CCY],Results!$B8)+SUMIFS(T_bETFs[Coupon in CCY],T_bETFs[Risk CCY],$B8)+SUMIFS(T_deposits[Coupon in Loc.Curr],T_deposits[Risk CCY],$B8)+SUMIFS(T_Eq[Dividend in Loc.Curr],T_Eq[Risk CCY],B8))/(SUMIFS(T_Bonds[Quantity],T_Bonds[Risk CCY],$B8)+SUMIFS(T_bETFs[Market Value, CCY],T_bETFs[Risk CCY],B8)+SUMIFS(T_deposits[Quantity],T_deposits[Risk CCY],B8)+SUMIFS(T_Eq[Market value, CCY],T_Eq[Risk CCY],B8)),"") -> 0.10375 | E8: =IFERROR((SUMIFS(T_Bonds[Coupon in Loc.Curr],T_Bonds[Risk CCY],Results!$B8)+SUMIFS(T_bETFs[Coupon in CCY],T_bETFs[Risk CCY],$B8)+SUMIFS(T_deposits[Coupon in Loc.Curr],T_deposits[Risk CCY],$B8)+SUMIFS(T_Eq[Dividend in Loc.Curr],T_Eq[Risk CCY],B8))/ (SUMIFS(T_Bonds[Cost value],T_Bonds[Risk CCY],$B8)+SUMIFS(T_bETFs[Market Value, CCY],T_bETFs[Risk CCY],$B8)+SUMIFS(T_deposits[Quantity],T_deposits[Risk CCY],$B8)+SUMIFS(T_Eq[Market value, CCY],T_Eq[Risk CCY],B8)),"") -> 0.11026809 | F8: =IFERROR( SUMIFS(T_Bonds[Coupon in Loc.Curr],T_Bonds[Risk CCY],Results!$B8)+ SUMIFS(T_bETFs[Coupon in CCY],T_bETFs[Risk CCY],$B8)+ SUMIFS(T_deposits[Coupon in Loc.Curr],T_deposits[Risk CCY],$B8)+ SUMIFS(T_Eq[Dividend in Loc.Curr],T_Eq[Risk CCY],B8)+ SUMIFS('Real Estate'!X:X,'Real Estate'!D:D,B8),"") -> 1245000 | G8: =IFERROR( SUMIFS(T_Bonds[Coupon in USD],T_Bonds[Risk CCY],Results!$B8)+ SUMIFS(T_bETFs[Coupon in USD],T_bETFs[Risk CCY],$B8)+ SUMIFS(T_deposits[Coupon in USD],T_deposits[Risk CCY],$B8)+ SUMIFS(T_Eq[Dividend in USD],T_Eq[Risk CCY],B8)+ SUMIFS('Real Estate'!Y:Y,'Real Estate'!D:D,B8),"") -> 239040 | H8: =IFERROR((SUMIFS(T_Bonds[Full MV in CCY],T_Bonds[Risk CCY],Results!$B8)+ SUMIFS(T_bETFs[Market value in CCY],T_bETFs[Risk CCY],$B8)+ SUMIFS(T_deposits[Market value in USD],T_deposits[Risk CCY],$B8)+ SUMIFS(T_Eq[Market value, CCY],T_Eq[Risk CCY],$B8)+ SUMIFS(T_AI[Market value in CCY],T_AI[Risk CCY],$B8)+ SUMIFS(Cash!F:F,Cash!E:E,$B8))+ SUMIFS('Real Estate'!$G:$G,'Real Estate'!$D:$D,B8)+ SUMIFS('JPM - DP (3R)'!$F:$F,'JPM - DP (3R)'!$C:$C,B8),"") -> 12406572 | I8: =IFERROR((SUMIFS(T_Bonds[Full MV in USD],T_Bonds[Risk CCY],Results!$B8)+ SUMIFS(T_bETFs[Market value in USD],T_bETFs[Risk CCY],$B8)+ SUMIFS(T_deposits[Market value in USD],T_deposits[Risk CCY],$B8)+ SUMIFS(T_Eq[Market value, USD],T_Eq[Risk CCY],$B8)+ SUMIFS(T_AI[Market value in USD],T_AI[Risk CCY],$B8)+ SUMIFS(Cash!H:H,Cash!E:E,$B8)+ SUMIFS('Real Estate'!$F:$F,'Real Estate'!$D:$D,B8)+ SUMIFS('JPM - DP (3R)'!$J:$J,'JPM - DP (3R)'!$C:$C,Results!B8)),"") -> 2382061.9 | S8: JPY | T8: {=IFERROR(SUMPRODUCT(Loans!D:D,Loans!F:F,IF(Loans!C:C=LTV!F9,1,0))/SUMIFS(Loans!D:D,Loans!C:C,LTV!F9),0)} -> 0.015 | U8: =-SUMIFS(Loans!D:D,Loans!C:C,LTV!F9) -> 148246000 | V8: =-SUMIFS(Loans!G:G,Loans!C:C,LTV!F9) -> 935728.75 | W8: =U8*T8 -> 2223690 | X8: =INDEX('Tech list'!$A$2:$C$8,MATCH(S8,'Tech list'!$A$2:$A$8,0),3)*W8 -> 14035.931 | Y8: 0
B9: TRY | C9: =I9/$I$11 -> 0.016885032 | D9: =IFERROR((SUMIFS(T_Bonds[Coupon in Loc.Curr],T_Bonds[Risk CCY],Results!$B9)+SUMIFS(T_bETFs[Coupon in CCY],T_bETFs[Risk CCY],$B9)+SUMIFS(T_deposits[Coupon in Loc.Curr],T_deposits[Risk CCY],$B9)+SUMIFS(T_Eq[Dividend in Loc.Curr],T_Eq[Risk CCY],B9))/(SUMIFS(T_Bonds[Quantity],T_Bonds[Risk CCY],$B9)+SUMIFS(T_bETFs[Market Value, CCY],T_bETFs[Risk CCY],B9)+SUMIFS(T_deposits[Quantity],T_deposits[Risk CCY],B9)+SUMIFS(T_Eq[Market value, CCY],T_Eq[Risk CCY],B9)),"") -> 0.275 | E9: =IFERROR((SUMIFS(T_Bonds[Coupon in Loc.Curr],T_Bonds[Risk CCY],Results!$B9)+SUMIFS(T_bETFs[Coupon in CCY],T_bETFs[Risk CCY],$B9)+SUMIFS(T_deposits[Coupon in Loc.Curr],T_deposits[Risk CCY],$B9)+SUMIFS(T_Eq[Dividend in Loc.Curr],T_Eq[Risk CCY],B9))/ (SUMIFS(T_Bonds[Cost value],T_Bonds[Risk CCY],$B9)+SUMIFS(T_bETFs[Market Value, CCY],T_bETFs[Risk CCY],$B9)+SUMIFS(T_deposits[Quantity],T_deposits[Risk CCY],$B9)+SUMIFS(T_Eq[Market value, CCY],T_Eq[Risk CCY],B9)),"") -> 0.30082429 | F9: =IFERROR( SUMIFS(T_Bonds[Coupon in Loc.Curr],T_Bonds[Risk CCY],Results!$B9)+ SUMIFS(T_bETFs[Coupon in CCY],T_bETFs[Risk CCY],$B9)+ SUMIFS(T_deposits[Coupon in Loc.Curr],T_deposits[Risk CCY],$B9)+ SUMIFS(T_Eq[Dividend in Loc.Curr],T_Eq[Risk CCY],B9)+ SUMIFS('Real Estate'!X:X,'Real Estate'!D:D,B9),"") -> 9020000 | G9: =IFERROR( SUMIFS(T_Bonds[Coupon in USD],T_Bonds[Risk CCY],Results!$B9)+ SUMIFS(T_bETFs[Coupon in USD],T_bETFs[Risk CCY],$B9)+ SUMIFS(T_deposits[Coupon in USD],T_deposits[Risk CCY],$B9)+ SUMIFS(T_Eq[Dividend in USD],T_Eq[Risk CCY],B9)+ SUMIFS('Real Estate'!Y:Y,'Real Estate'!D:D,B9),"") -> 204754 | H9: =IFERROR((SUMIFS(T_Bonds[Full MV in CCY],T_Bonds[Risk CCY],Results!$B9)+ SUMIFS(T_bETFs[Market value in CCY],T_bETFs[Risk CCY],$B9)+ SUMIFS(T_deposits[Market value in USD],T_deposits[Risk CCY],$B9)+ SUMIFS(T_Eq[Market value, CCY],T_Eq[Risk CCY],$B9)+ SUMIFS(T_AI[Market value in CCY],T_AI[Risk CCY],$B9)+ SUMIFS(Cash!F:F,Cash!E:E,$B9))+ SUMIFS('Real Estate'!$G:$G,'Real Estate'!$D:$D,B9)+ SUMIFS('JPM - DP (3R)'!$F:$F,'JPM - DP (3R)'!$C:$C,B9),"") -> 40710267 | I9: =IFERROR((SUMIFS(T_Bonds[Full MV in USD],T_Bonds[Risk CCY],Results!$B9)+ SUMIFS(T_bETFs[Market value in USD],T_bETFs[Risk CCY],$B9)+ SUMIFS(T_deposits[Market value in USD],T_deposits[Risk CCY],$B9)+ SUMIFS(T_Eq[Market value, USD],T_Eq[Risk CCY],$B9)+ SUMIFS(T_AI[Market value in USD],T_AI[Risk CCY],$B9)+ SUMIFS(Cash!H:H,Cash!E:E,$B9)+ SUMIFS('Real Estate'!$F:$F,'Real Estate'!$D:$D,B9)+ SUMIFS('JPM - DP (3R)'!$J:$J,'JPM - DP (3R)'!$C:$C,Results!B9)),"") -> 924123.05 | V9: =SUM(V4:V8) -> 49481316 | X9: =SUM(X4:X8) -> 959760.96
B10: Other (JPM DP) | C10: =I10/$I$11 -> 0.011918192 | F10: =IFERROR( SUMIFS(T_Bonds[Coupon in Loc.Curr],T_Bonds[Risk CCY],Results!$B10)+ SUMIFS(T_bETFs[Coupon in CCY],T_bETFs[Risk CCY],$B10)+ SUMIFS(T_deposits[Coupon in Loc.Curr],T_deposits[Risk CCY],$B10)+ SUMIFS(T_Eq[Dividend in Loc.Curr],T_Eq[Risk CCY],B10)+ SUMIFS('Real Estate'!X:X,'Real Estate'!D:D,B10),"") -> 0 | G10: =IFERROR( SUMIFS(T_Bonds[Coupon in USD],T_Bonds[Risk CCY],Results!$B10)+ SUMIFS(T_bETFs[Coupon in USD],T_bETFs[Risk CCY],$B10)+ SUMIFS(T_deposits[Coupon in USD],T_deposits[Risk CCY],$B10)+ SUMIFS(T_Eq[Dividend in USD],T_Eq[Risk CCY],B10)+ SUMIFS('Real Estate'!Y:Y,'Real Estate'!D:D,B10),"") -> 0 | H10: =IFERROR((SUMIFS(T_Bonds[Full MV in CCY],T_Bonds[Risk CCY],Results!$B10)+ SUMIFS(T_bETFs[Market value in CCY],T_bETFs[Risk CCY],$B10)+ SUMIFS(T_deposits[Market value in USD],T_deposits[Risk CCY],$B10)+ SUMIFS(T_Eq[Market value, CCY],T_Eq[Risk CCY],$B10)+ SUMIFS(T_AI[Market value in CCY],T_AI[Risk CCY],$B10)+ SUMIFS(Cash!F:F,Cash!E:E,$B10))+ SUMIFS('Real Estate'!$G:$G,'Real Estate'!$D:$D,B10)+ SUMIFS('JPM - DP (3R)'!$F:$F,'JPM - DP (3R)'!$C:$C,B10),"") -> 0 | I10: ='JPM - DP (3R)'!$X$37 -> 652286.37
D11: =SUMPRODUCT(C4:C9,D4:D9) -> #VALUE! | E11: =SUMPRODUCT($C$4:$C$9,E4:E9) -> #VALUE! | G11: =SUM(G4:G10) -> 2983081.5 | I11: =SUM(I4:I10)+I68+I70 -> 54730311
B13: Bonds
B14: Currency | C14: Weights | D14: AW coupon (CCY) | E14: AW Current yield (CCY) | F14: Total coupon (CCY) | G14: Total coupon (USD) | H14: Total MV of positions (CCY) | I14: Total MV of positions (USD) | J14: YTM/YTC | S14: Portfolio Loans, Current by bank '000
B15: USD | C15: =SUMIFS(T_Bonds[Market value in USD],T_Bonds[Risk CCY],Results!B4)/SUM(T_Bonds[Market value in USD]) -> 0.66087242 | D15: =SUMIFS(T_Bonds[Coupon in Loc.Curr],T_Bonds[Risk CCY],Results!$B15)/SUMIFS(T_Bonds[Quantity],T_Bonds[Risk CCY],$B15) -> 0.067320568 | E15: =SUMIFS(T_Bonds[Coupon in Loc.Curr],T_Bonds[Risk CCY],Results!$B15)/SUMIFS(T_Bonds[Cost value],T_Bonds[Risk CCY],$B15) -> 0.073590258 | F15: =SUMIFS(T_Bonds[Coupon in Loc.Curr],T_Bonds[Risk CCY],Results!$B15) -> 3261681.5 | G15: =SUMIFS(T_Bonds[Coupon in USD],T_Bonds[Risk CCY],Results!$B15) -> 3261681.5 | H15: =SUMIFS(T_Bonds[Full MV in CCY],T_Bonds[Risk CCY],Results!$B15) -> 47090795 | I15: =SUMIFS(T_Bonds[Full MV in USD],T_Bonds[Risk CCY],Results!$B15) -> 47090795 | J15: =SUMIFS(T_Bonds[for WYTC],T_Bonds[Risk CCY],Results!B15)/ (SUMIFS(T_Bonds[Quantity],T_Bonds[Risk CCY],Results!B15)- SUMIFS(T_Bonds[Quantity],T_Bonds[Risk CCY],Results!B15,T_Bonds[YTM/YTC],0)) -> 0.072490096 | S15: CCY | T15: JPM | U15: UBS | V15: Vontobel
B16: GBP | C16: =SUMIFS(T_Bonds[Market value in USD],T_Bonds[Risk CCY],Results!B5)/SUM(T_Bonds[Market value in USD]) -> 0.16705908 | D16: =SUMIFS(T_Bonds[Coupon in Loc.Curr],T_Bonds[Risk CCY],Results!$B16)/SUMIFS(T_Bonds[Quantity],T_Bonds[Risk CCY],$B16) -> 0.064311489 | E16: =SUMIFS(T_Bonds[Coupon in Loc.Curr],T_Bonds[Risk CCY],Results!$B16)/SUMIFS(T_Bonds[Cost value],T_Bonds[Risk CCY],$B16) -> 0.072290702 | F16: =SUMIFS(T_Bonds[Coupon in Loc.Curr],T_Bonds[Risk CCY],Results!$B16) -> 604528 | G16: =SUMIFS(T_Bonds[Coupon in USD],T_Bonds[Risk CCY],Results!$B16) -> 808495.75 | H16: =SUMIFS(T_Bonds[Full MV in CCY],T_Bonds[Risk CCY],Results!$B16) -> 9050996.4 | I16: =SUMIFS(T_Bonds[Full MV in USD],T_Bonds[Risk CCY],Results!$B16) -> 12104803 | J16: =SUMIFS(T_Bonds[for WYTC],T_Bonds[Risk CCY],Results!B16)/(SUMIFS(T_Bonds[Quantity],T_Bonds[Risk CCY],Results!B16)-SUMIFS(T_Bonds[Quantity],T_Bonds[Risk CCY],Results!B16,T_Bonds[YTM/YTC],0)) -> 0.070114952 | S16: USD | T16: =SUMIFS(Loans!$D:$D,Loans!$C:$C,Results!$S16,Loans!$A:$A,Results!T$15)/1000 -> -210.49239 | U16: =SUMIFS(Loans!$D:$D,Loans!$C:$C,Results!$S16,Loans!$A:$A,Results!U$15)/1000 -> 0 | V16: =SUMIFS(Loans!$D:$D,Loans!$C:$C,Results!$S16,Loans!$A:$A,Results!V$15)/1000 -> 0
B17: EUR | C17: =SUMIFS(T_Bonds[Market value in USD],T_Bonds[Risk CCY],Results!B6)/SUM(T_Bonds[Market value in USD]) -> 0.13006061 | D17: =SUMIFS(T_Bonds[Coupon in Loc.Curr],T_Bonds[Risk CCY],Results!$B17)/SUMIFS(T_Bonds[Quantity],T_Bonds[Risk CCY],$B17) -> 0.066554054 | E17: =SUMIFS(T_Bonds[Coupon in Loc.Curr],T_Bonds[Risk CCY],Results!$B17)/SUMIFS(T_Bonds[Cost value],T_Bonds[Risk CCY],$B17) -> 0.066466178 | F17: =SUMIFS(T_Bonds[Coupon in Loc.Curr],T_Bonds[Risk CCY],Results!$B17) -> 492500 | G17: =SUMIFS(T_Bonds[Coupon in USD],T_Bonds[Risk CCY],Results!$B17) -> 569871.75 | H17: =SUMIFS(T_Bonds[Full MV in CCY],T_Bonds[Risk CCY],Results!$B17) -> 7979789.6 | I17: =SUMIFS(T_Bonds[Full MV in USD],T_Bonds[Risk CCY],Results!$B17) -> 9233414.5 | J17: =SUMIFS(T_Bonds[for WYTC],T_Bonds[Risk CCY],Results!B17)/(SUMIFS(T_Bonds[Quantity],T_Bonds[Risk CCY],Results!B17)-SUMIFS(T_Bonds[Quantity],T_Bonds[Risk CCY],Results!B17,T_Bonds[YTM/YTC],0)) -> 0.055439351 | S17: GBP | T17: =SUMIFS(Loans!$D:$D,Loans!$C:$C,Results!$S17,Loans!$A:$A,Results!T$15)/1000 -> -1467.0865 | U17: =SUMIFS(Loans!$D:$D,Loans!$C:$C,Results!$S17,Loans!$A:$A,Results!U$15)/1000 -> 0 | V17: =SUMIFS(Loans!$D:$D,Loans!$C:$C,Results!$S17,Loans!$A:$A,Results!V$15)/1000 -> -240
B18: BRL | C18: =SUMIFS(T_Bonds[Market value in USD],T_Bonds[Risk CCY],Results!B8)/SUM(T_Bonds[Market value in USD]) -> 0.031904403 | D18: =SUMIFS(T_Bonds[Coupon in Loc.Curr],T_Bonds[Risk CCY],Results!$B18)/SUMIFS(T_Bonds[Quantity],T_Bonds[Risk CCY],$B18) -> 0.10375 | E18: =SUMIFS(T_Bonds[Coupon in Loc.Curr],T_Bonds[Risk CCY],Results!$B18)/SUMIFS(T_Bonds[Cost value],T_Bonds[Risk CCY],$B18) -> 0.11026809 | F18: =SUMIFS(T_Bonds[Coupon in Loc.Curr],T_Bonds[Risk CCY],Results!$B18) -> 1245000 | G18: =SUMIFS(T_Bonds[Coupon in USD],T_Bonds[Risk CCY],Results!$B18) -> 239040 | H18: =SUMIFS(T_Bonds[Full MV in CCY],T_Bonds[Risk CCY],Results!$B18) -> 12406572 | I18: =SUMIFS(T_Bonds[Full MV in USD],T_Bonds[Risk CCY],Results!$B18) -> 2382061.9 | J18: =SUMIFS(T_Bonds[for WYTC],T_Bonds[Risk CCY],Results!B18)/(SUMIFS(T_Bonds[Quantity],T_Bonds[Risk CCY],Results!B18)-SUMIFS(T_Bonds[Quantity],T_Bonds[Risk CCY],Results!B18,T_Bonds[YTM/YTC],0)) -> 0.11900345 | S18: EUR | T18: =SUMIFS(Loans!$D:$D,Loans!$C:$C,Results!$S18,Loans!$A:$A,Results!T$15)/1000 -> -5388.8953 | U18: =SUMIFS(Loans!$D:$D,Loans!$C:$C,Results!$S18,Loans!$A:$A,Results!U$15)/1000 -> -2265.693 | V18: =SUMIFS(Loans!$D:$D,Loans!$C:$C,Results!$S18,Loans!$A:$A,Results!V$15)/1000 -> -17018
B19: TRY | C19: =SUMIFS(T_Bonds[Market value in USD],T_Bonds[Risk CCY],Results!B9)/SUM(T_Bonds[Market value in USD]) -> 0.010103489 | D19: =SUMIFS(T_Bonds[Coupon in Loc.Curr],T_Bonds[Risk CCY],Results!$B19)/SUMIFS(T_Bonds[Quantity],T_Bonds[Risk CCY],$B19) -> 0.275 | E19: =SUMIFS(T_Bonds[Coupon in Loc.Curr],T_Bonds[Risk CCY],Results!$B19)/SUMIFS(T_Bonds[Cost value],T_Bonds[Risk CCY],$B19) -> 0.30082429 | F19: =SUMIFS(T_Bonds[Coupon in Loc.Curr],T_Bonds[Risk CCY],Results!$B19) -> 9020000 | G19: =SUMIFS(T_Bonds[Coupon in USD],T_Bonds[Risk CCY],Results!$B19) -> 204754 | H19: =SUMIFS(T_Bonds[Full MV in CCY],T_Bonds[Risk CCY],Results!$B19) -> 40710267 | I19: =SUMIFS(T_Bonds[Full MV in USD],T_Bonds[Risk CCY],Results!$B19) -> 924123.05 | J19: =SUMIFS(T_Bonds[for WYTC],T_Bonds[Risk CCY],Results!B19)/(SUMIFS(T_Bonds[Quantity],T_Bonds[Risk CCY],Results!B19)-SUMIFS(T_Bonds[Quantity],T_Bonds[Risk CCY],Results!B19,T_Bonds[YTM/YTC],0)) -> 0.31121346 | S19: CHF | T19: =SUMIFS(Loans!$D:$D,Loans!$C:$C,Results!$S19,Loans!$A:$A,Results!T$15)/1000 -> -25.7689 | U19: =SUMIFS(Loans!$D:$D,Loans!$C:$C,Results!$S19,Loans!$A:$A,Results!U$15)/1000 -> -2000 | V19: =SUMIFS(Loans!$D:$D,Loans!$C:$C,Results!$S19,Loans!$A:$A,Results!V$15)/1000 -> -11614.65
D20: =SUMPRODUCT($C$15:$C$19,D15:D19) -> 0.069978727 | E20: =SUMPRODUCT($C$15:$C$19,E15:E19) -> 0.075912634 | G20: =SUM(G15:G19) -> 5083843 | I20: =SUM(I15:I19) -> 71735197 | J20: =SUMPRODUCT($C$15:$C$19,J15:J19) -> 0.073771596 | M20: Bonds | N20: =I20/I11 -> 1.3107033 | S20: JPY | T20: =SUMIFS(Loans!$D:$D,Loans!$C:$C,Results!$S20,Loans!$A:$A,Results!T$15)/1000 -> 0 | U20: =SUMIFS(Loans!$D:$D,Loans!$C:$C,Results!$S20,Loans!$A:$A,Results!U$15)/1000 -> 0 | V20: =SUMIFS(Loans!$D:$D,Loans!$C:$C,Results!$S20,Loans!$A:$A,Results!V$15)/1000 -> -148246
M21: Deposits | N21: =I27/I11 -> 0.23653137 | S21: Total in USD | T21: =SUMIFS(Loans!$G:$G,Loans!$A:$A,Results!T$15)/1000 -> -8441.1313 | U21: =SUMIFS(Loans!$G2:$G20,Loans!$A2:$A20,Results!U$15)/1000 -> -5188.0334 | V21: =SUMIFS(Loans!$G2:$G20,Loans!$A2:$A20,Results!V$15)/1000 -> -35852.151
M22: Bond Funds | N22: =I34/I11 -> 0.6799215
B23: Deposits | M23: Equities (incl. ETF) | N23: =I44/I11 -> #N/A
B24: Currency | C24: Weights | D24: AW % (no reinvest) | E24: AW % (with reinvest) | F24: Interest, CCY 2024 | G24: Interest, USD 2024 | H24: Total MV of positions, CCY | I24: Total MV of positions (USD) | M24: AI | N24: =I52/I11 -> 0.17406237 | S24: =LTV!F25 -> LTV by banks (Collateral assets) | V24: =LTV!I25 -> In tousands of USD
B25: USD | C25: =SUMIFS(Deposits!U:U,Deposits!D:D,Results!B4)/SUM(Deposits!V:V) -> 1 | D25: =IFERROR(SUMIFS(T_deposits[Coupon in Loc.Curr],T_deposits[Risk CCY],Results!$B25)/SUMIFS(T_deposits[Quantity],T_deposits[Risk CCY],Results!$B25),"") -> 0.037294218 | E25: =IFERROR(SUMIFS(#REF!,T_deposits[Risk CCY],Results!$B25)/SUMIFS(T_deposits[Quantity],T_deposits[Risk CCY],Results!$B25),"") | F25: =SUMIFS(T_deposits[Coupon in Loc.Curr],T_deposits[Risk CCY],Results!B25) -> 379207.61 | G25: =SUMIFS(T_deposits[Coupon in USD, real],T_deposits[Risk CCY],Results!B25) -> 374581.66 | H25: =SUMIFS(T_deposits[Market value in USD],T_deposits[Risk CCY],Results!B25) -> 12945435 | I25: =SUMIFS(T_deposits[Market value in USD],T_deposits[Risk CCY],Results!B25) -> 12945435 | M25: Real Estate | N25: =I60/I11 -> 1.3166054 | S25: =LTV!F26 -> Bank | T25: =LTV!G26 -> Collateral Market Value | U25: =LTV!H26 -> Loans | V25: =LTV!I26 -> LTV
B26: GBP | C26: =SUMIFS(Deposits!U:U,Deposits!D:D,Results!B5)/SUM(Deposits!V:V) -> 0 | D26: =IFERROR(SUMIFS(T_deposits[Coupon in Loc.Curr],T_deposits[Risk CCY],Results!$B26)/SUMIFS(T_deposits[Quantity],T_deposits[Risk CCY],Results!$B26),"") | E26: =IFERROR(SUMIFS(#REF!,T_deposits[Risk CCY],Results!$B26)/SUMIFS(T_deposits[Quantity],T_deposits[Risk CCY],Results!$B26),"") | F26: =SUMIFS(T_deposits[Coupon in Loc.Curr],T_deposits[Risk CCY],Results!B26) -> 0 | G26: =SUMIFS(T_deposits[Coupon in USD],T_deposits[Risk CCY],Results!B26) -> 0 | H26: =SUMIFS(T_deposits[Quantity],T_deposits[Risk CCY],Results!B26) -> 0 | I26: =SUMIFS(T_deposits[Market value in USD],T_deposits[Risk CCY],Results!B26) -> 0 | M26: Cash | N26: =I73/I11 -> -0.047473235 | S26: =LTV!F27 -> Vontobel | T26: =LTV!G27 -> #VALUE! | U26: =LTV!H27 -> 35852.151 | V26: =LTV!I27 -> #VALUE!
D27: =SUMPRODUCT(C25:C26,D25:D26) -> 0.037294218 | E27: =SUMPRODUCT(C25:C26,E25:E26) -> 0 | G27: =SUM(G24:G26) -> 374581.66 | I27: =SUM(I24:I26) -> 12945435 | S27: =LTV!F28 -> UBS | T27: =LTV!G28 -> 20902.871 | U27: =LTV!H28 -> 5188.0334 | V27: =LTV!I28 -> 0.24819717
S28: =LTV!F29 -> JPM | T28: =LTV!G29 -> 25945.878 | U28: =LTV!H29 -> 8441.1313 | V28: =LTV!I29 -> 0.32533612
S29: =LTV!F30 -> Total in USD | T29: =LTV!G30 -> #VALUE! | U29: =LTV!H30 -> 49481.316 | V29: =LTV!I30 -> #VALUE!
B30: Bonds ETF
B31: Currency | C31: Weights | D31: AW % | E31: Gross P&L | F31: Distributions, CCY 2024 | G31: Distributions, USD 2024 | H31: Total MV of funds (CCY) | I31: Total MV of funds (USD)
B32: USD | C32: =I32/$I$34 -> 1 | D32: =IFERROR(SUMIFS(T_bETFs[Coupon in CCY],T_bETFs[Risk CCY],Results!B32)/SUMIFS(T_bETFs[Market Value, CCY],T_bETFs[Risk CCY],Results!B32),"") -> 0.066976206 | E32: =IFERROR(SUMIFS('Bonds ETFs'!R:R,'Bonds ETFs'!O:O,Results!B32)/SUMIFS('Bonds ETFs'!Z:Z,'Bonds ETFs'!O:O,Results!B32)-1,"") -> -0.050186672 | F32: =SUMIFS(T_bETFs[Coupon in CCY],T_bETFs[Risk CCY],Results!B32) -> 2492339.7 | G32: =SUMIFS(T_bETFs[Coupon in USD],T_bETFs[Risk CCY],Results!B32) -> 2492339.7 | H32: =SUMIFS(T_bETFs[Market Value, CCY],T_bETFs[Risk CCY],Results!B32) -> 37212315 | I32: =SUMIFS(T_bETFs[Market Value, USD],T_bETFs[Risk CCY],Results!B32) -> 37212315 | S32: =LTV!F34 -> LTV by banks (All assets) | V32: =LTV!I34 -> In tousands of USD
B33: EUR | C33: =I33/$I$34 -> 0 | D33: =IFERROR(SUMIFS(T_bETFs[Coupon in CCY],T_bETFs[Risk CCY],Results!B33)/SUMIFS(T_bETFs[Market Value, CCY],T_bETFs[Risk CCY],Results!B33),"") | E33: =IFERROR(SUMIFS('Bonds ETFs'!R:R,'Bonds ETFs'!O:O,Results!B33)/SUMIFS('Bonds ETFs'!Z:Z,'Bonds ETFs'!O:O,Results!B33)-1,"") | F33: =SUMIFS(T_bETFs[Coupon in CCY],T_bETFs[Risk CCY],Results!B33) -> 0 | G33: =SUMIFS(T_bETFs[Coupon in USD],T_bETFs[Risk CCY],Results!B33) -> 0 | H33: =SUMIFS(T_bETFs[Market Value, CCY],T_bETFs[Risk CCY],Results!B33) -> 0 | I33: =SUMIFS(T_bETFs[Market Value, USD],T_bETFs[Risk CCY],Results!B33) -> 0 | S33: =LTV!F35 -> Bank | T33: =LTV!G35 -> Market Value | U33: =LTV!H35 -> Loans | V33: =LTV!I35 -> LTV
G34: =SUM(G32:G33) -> 2492339.7 | I34: =SUM(I32:I33) -> 37212315 | S34: =LTV!F36 -> Vontobel | T34: =LTV!G36 -> #VALUE! | U34: =LTV!H36 -> 35852.151 | V34: =LTV!I36 -> -
S35: =LTV!F37 -> UBS | T35: =LTV!G37 -> 20902.871 | U35: =LTV!H37 -> 5188.0334 | V35: =LTV!I37 -> 0.24819717
S36: =LTV!F38 -> JPM | T36: =LTV!G38 -> 35945.878 | U36: =LTV!H38 -> 8441.1313 | V36: =LTV!I38 -> 0.23482891
B37: Equities | S37: =LTV!F39 -> Non-bank | T37: =LTV!G39 -> 53636.191 | U37: =LTV!H39 -> 0 | V37: =LTV!I39 -> 0
B38: CCY | C38: Weights | D38: AW yield, CCY | E38: P&L, total | F38: Total annual DIV, CCY | G38: Total annual DIV, USD | H38: Total MV of positions (CCY) | I38: Total MV of positions (USD) | S38: =LTV!F40 -> Total in USD | T38: =LTV!G40 -> #VALUE! | U38: =LTV!H40 -> 49481.316 | V38: =LTV!I40 -> -
B39: USD | C39: =I39/$I$44 -> #N/A | D39: =SUMIFS(T_Eq[Dividend in Loc.Curr],T_Eq[Risk CCY],B39)/SUMIFS(T_Eq[Market value, CCY],T_Eq[Risk CCY],B39) -> #N/A | E39: =SUMIFS(T_Eq[Market value, CCY],T_Eq[Risk CCY],B39)/SUMIFS(T_Eq[Cost value],T_Eq[Risk CCY],B39)-1 -> #N/A | F39: =SUMIFS(T_Eq[Dividend in Loc.Curr],T_Eq[Risk CCY],B39) -> #N/A | G39: =SUMIFS(T_Eq[Dividend in USD],T_Eq[Risk CCY],B39) -> #N/A | H39: =SUMIFS(T_Eq[Market value, CCY],T_Eq[Risk CCY],B39) -> #N/A | I39: =SUMIFS(T_Eq[Market value, USD],T_Eq[Risk CCY],B39) -> #N/A
B40: EUR | C40: =I40/$I$44 -> #N/A | D40: =SUMIFS(T_Eq[Dividend in Loc.Curr],T_Eq[Risk CCY],B40)/SUMIFS(T_Eq[Market value, CCY],T_Eq[Risk CCY],B40) -> #N/A | E40: =SUMIFS(T_Eq[Market value, CCY],T_Eq[Risk CCY],B40)/SUMIFS(T_Eq[Cost value],T_Eq[Risk CCY],B40)-1 -> #N/A | F40: =SUMIFS(T_Eq[Dividend in Loc.Curr],T_Eq[Risk CCY],B40) -> #N/A | G40: =SUMIFS(T_Eq[Dividend in USD],T_Eq[Risk CCY],B40) -> #N/A | H40: =SUMIFS(T_Eq[Market value, CCY],T_Eq[Risk CCY],B40) -> #N/A | I40: =SUMIFS(T_Eq[Market value, USD],T_Eq[Risk CCY],B40) -> #N/A
B41: GBP | C41: =I41/$I$44 -> #N/A | D41: =SUMIFS(T_Eq[Dividend in Loc.Curr],T_Eq[Risk CCY],B41)/SUMIFS(T_Eq[Market value, CCY],T_Eq[Risk CCY],B41) -> 0.055718021 | E41: =SUMIFS(T_Eq[Market value, CCY],T_Eq[Risk CCY],B41)/SUMIFS(T_Eq[Cost value],T_Eq[Risk CCY],B41)-1 -> 0.15332466 | F41: =SUMIFS(T_Eq[Dividend in Loc.Curr],T_Eq[Risk CCY],B41) -> 93699.514 | G41: =SUMIFS(T_Eq[Dividend in USD],T_Eq[Risk CCY],B41) -> 125313.73 | H41: =SUMIFS(T_Eq[Market value, CCY],T_Eq[Risk CCY],B41) -> 1681673.4 | I41: =SUMIFS(T_Eq[Market value, USD],T_Eq[Risk CCY],B41) -> 2249070
B42: CAD | C42: =I42/$I$44 -> #N/A | D42: =SUMIFS(T_Eq[Dividend in Loc.Curr],T_Eq[Risk CCY],B42)/SUMIFS(T_Eq[Market value, CCY],T_Eq[Risk CCY],B42) -> 0.0011969776 | E42: =SUMIFS(T_Eq[Market value, CCY],T_Eq[Risk CCY],B42)/SUMIFS(T_Eq[Cost value],T_Eq[Risk CCY],B42)-1 -> 1.8361994 | F42: =SUMIFS(T_Eq[Dividend in Loc.Curr],T_Eq[Risk CCY],B42) -> 812 | G42: =SUMIFS(T_Eq[Dividend in USD],T_Eq[Risk CCY],B42) -> 598.038 | H42: =SUMIFS(T_Eq[Market value, CCY],T_Eq[Risk CCY],B42) -> 678375.25 | I42: =SUMIFS(T_Eq[Market value, USD],T_Eq[Risk CCY],B42) -> 499623.37 | S42: JPM Discretionary part Results
...

Sheet LTV
F3: Total Loans, by CCY
F4: CCY | G4: Cost of debt, 2025 | H4: Curent debt CCY | I4: Current Debt USD | J4: Annual interest, CCY | K4: Annual interest, USD | L4: Total coupon, CCY
F5: USD | G5: {=IFERROR(SUMPRODUCT(Loans!D:D,Loans!F:F,IF(Loans!C:C=LTV!F5,1,0))/SUMIFS(Loans!D:D,Loans!C:C,LTV!F5),0)} -> 0.044834337 | H5: =-SUMIFS(Loans!D:D,Loans!C:C,LTV!F5) -> 210492.39 | I5: =-SUMIFS(Loans!G:G,Loans!C:C,LTV!F5) -> 210492.39 | J5: =H5*G5 -> 9437.2868 | K5: =INDEX('Tech list'!$A$2:$C$8,MATCH(F5,'Tech list'!$A$2:$A$8,0),3)*J5 -> 9437.2868 | L5: =IFERROR(VLOOKUP(F5,Results!$B$4:$F$9,5,0),"-")
F6: GBP | G6: {=IFERROR(SUMPRODUCT(Loans!D:D,Loans!F:F,IF(Loans!C:C=LTV!F6,1,0))/SUMIFS(Loans!D:D,Loans!C:C,LTV!F6),0)} -> 0.043572191 | H6: =-SUMIFS(Loans!D:D,Loans!C:C,LTV!F6) -> 1707086.5 | I6: =-SUMIFS(Loans!G:G,Loans!C:C,LTV!F6) -> 2283057.5 | J6: =H6*G6 -> 74381.498 | K6: =INDEX('Tech list'!$A$2:$C$8,MATCH(F6,'Tech list'!$A$2:$A$8,0),3)*J6 -> 99477.815 | L6: =IFERROR(VLOOKUP(F6,Results!$B$4:$F$9,5,0),"-") -> 1898227.5
F7: EUR | G7: {=IFERROR(SUMPRODUCT(Loans!D:D,Loans!F:F,IF(Loans!C:C=LTV!F7,1,0))/SUMIFS(Loans!D:D,Loans!C:C,LTV!F7),0)} -> 0.025230202 | H7: =-SUMIFS(Loans!D:D,Loans!C:C,LTV!F7) -> 24672588 | I7: =-SUMIFS(Loans!G:G,Loans!C:C,LTV!F7) -> 28548652 | J7: =H7*G7 -> 622494.39 | K7: =INDEX('Tech list'!$A$2:$C$8,MATCH(F7,'Tech list'!$A$2:$A$8,0),3)*J7 -> 720288.25 | L7: =IFERROR(VLOOKUP(F7,Results!$B$4:$F$9,5,0),"-")
F8: CHF | G8: {=IFERROR(SUMPRODUCT(Loans!D:D,Loans!F:F,IF(Loans!C:C=LTV!F8,1,0))/SUMIFS(Loans!D:D,Loans!C:C,LTV!F8),0)} -> 0.0066570933 | H8: =-SUMIFS(Loans!D:D,Loans!C:C,LTV!F8) -> 13640419 | I8: =-SUMIFS(Loans!G:G,Loans!C:C,LTV!F8) -> 17503386 | J8: =H8*G8 -> 90805.541 | K8: =INDEX('Tech list'!$A$2:$C$8,MATCH(F8,'Tech list'!$A$2:$A$8,0),3)*J8 -> 116521.67 | L8: =IFERROR(VLOOKUP(F8,Results!$B$4:$F$9,5,0),"-") -> -
F9: JPY | G9: {=IFERROR(SUMPRODUCT(Loans!D:D,Loans!F:F,IF(Loans!C:C=LTV!F9,1,0))/SUMIFS(Loans!D:D,Loans!C:C,LTV!F9),0)} -> 0.015 | H9: =-SUMIFS(Loans!D:D,Loans!C:C,LTV!F9) -> 148246000 | I9: =-SUMIFS(Loans!G:G,Loans!C:C,LTV!F9) -> 935728.75 | J9: =H9*G9 -> 2223690 | K9: =INDEX('Tech list'!$A$2:$C$8,MATCH(F9,'Tech list'!$A$2:$A$8,0),3)*J9 -> 14035.931 | L9: =IFERROR(VLOOKUP(F9,Results!$B$4:$F$9,5,0),"-") -> -
I10: =SUM(I5:I9) -> 49481316 | K10: =SUM(K5:K9) -> 959760.96
F12: Total current Loans by bank '000
F13: CCY | G13: JPM | H13: UBS | I13: Vontobel
F14: USD | G14: =SUMIFS(Loans!$D:$D,Loans!$C:$C,LTV!$F14,Loans!$A:$A,LTV!G$13)/1000 -> -210.49239 | H14: =SUMIFS(Loans!$D:$D,Loans!$C:$C,LTV!$F14,Loans!$A:$A,LTV!H$13)/1000 -> 0 | I14: =SUMIFS(Loans!$D:$D,Loans!$C:$C,LTV!$F14,Loans!$A:$A,LTV!I$13)/1000 -> 0
F15: GBP | G15: =SUMIFS(Loans!$D:$D,Loans!$C:$C,LTV!$F15,Loans!$A:$A,LTV!G$13)/1000 -> -1467.0865 | H15: =SUMIFS(Loans!$D:$D,Loans!$C:$C,LTV!$F15,Loans!$A:$A,LTV!H$13)/1000 -> 0 | I15: =SUMIFS(Loans!$D:$D,Loans!$C:$C,LTV!$F15,Loans!$A:$A,LTV!I$13)/1000 -> -240
F16: EUR | G16: =SUMIFS(Loans!$D:$D,Loans!$C:$C,LTV!$F16,Loans!$A:$A,LTV!G$13)/1000 -> -5388.8953 | H16: =SUMIFS(Loans!$D:$D,Loans!$C:$C,LTV!$F16,Loans!$A:$A,LTV!H$13)/1000 -> -2265.693 | I16: =SUMIFS(Loans!$D:$D,Loans!$C:$C,LTV!$F16,Loans!$A:$A,LTV!I$13)/1000 -> -17018
F17: CHF | G17: =SUMIFS(Loans!$D:$D,Loans!$C:$C,LTV!$F17,Loans!$A:$A,LTV!G$13)/1000 -> -25.7689 | H17: =SUMIFS(Loans!$D:$D,Loans!$C:$C,LTV!$F17,Loans!$A:$A,LTV!H$13)/1000 -> -2000 | I17: =SUMIFS(Loans!$D:$D,Loans!$C:$C,LTV!$F17,Loans!$A:$A,LTV!I$13)/1000 -> -11614.65
F18: JPY | G18: =SUMIFS(Loans!$D:$D,Loans!$C:$C,LTV!$F18,Loans!$A:$A,LTV!G$13)/1000 -> 0 | H18: =SUMIFS(Loans!$D:$D,Loans!$C:$C,LTV!$F18,Loans!$A:$A,LTV!H$13)/1000 -> 0 | I18: =SUMIFS(Loans!$D:$D,Loans!$C:$C,LTV!$F18,Loans!$A:$A,LTV!I$13)/1000 -> -148246
F19: Total in USD | G19: =SUMIFS(Loans!$G:$G,Loans!$A:$A,LTV!G$13)/1000 -> -8441.1313 | H19: =SUMIFS(Loans!$G:$G,Loans!$A:$A,LTV!H$13)/1000 -> -5188.0334 | I19: =SUMIFS(Loans!$G:$G,Loans!$A:$A,LTV!I$13)/1000 -> -35852.151
B25: INPUTs for LTV Calculation (in thouthands of USD) | F25: LTV by banks (Collateral assets) | I25: In tousands of USD | K25: LTV Calculation (By facility) | S25: In tousands of USD
F26: Bank | G26: Collateral Market Value | H26: Loans | I26: LTV | K26: Bank | L26: Source | M26: Collateral Market Value | N26: Assets Adj. 1 | O26: Assets Adj. 2 | P26: Total loans | Q26: Loans Adj. | R26: LTV | S26: Collateral
B27: LHC bonds | C27: =IF(D27="Including",1,0) -> 1 | D27: Including | F27: Vontobel | G27: =SUMIFS($M$27:$M$30,$K$27:$K$30,F27) -> #VALUE! | H27: =SUMIFS($P$27:$P$30,$K$27:$K$30,F27) -> 35852.151 | I27: =H27/G27 -> #VALUE! | K27: Vontobel | L27: Vontobel | M27: =IFERROR((SUMIFS(Bonds!AC:AC,Bonds!B:B,LTV!L27)+ SUMIFS('Bonds ETFs'!S:S,'Bonds ETFs'!A:A,LTV!L27)+ SUMIFS(Deposits!V:V,Deposits!A:A,LTV!L27)+ SUMIFS(Equities!L:L,Equities!A:A,LTV!L27)+ SUMIFS('Alternative assets'!Z:Z,'Alternative assets'!A:A,LTV!L27)+ SUMIFS(Cash!H:H,Cash!A:A,LTV!L27)+ SUMIFS('JPM - DP (3R)'!$J:$J,'JPM - DP (3R)'!$A:$A,LTV!L27)),"")/1000*$N27+$O27 -> #VALUE! | N27: 1 | P27: =-(SUMIFS(Loans!G:G,Loans!A:A,L27)/1000+$Q27) -> 35852.151 | R27: =P27/M27 -> #VALUE! | S27: Antrarras portfolio in Vontobel
B28: Private Equity | C28: =IF(D28="Including",1,0) -> 1 | D28: Including | F28: UBS | G28: =SUMIFS($M$27:$M$30,$K$27:$K$30,F28) -> 20902.871 | H28: =SUMIFS($P$27:$P$30,$K$27:$K$30,F28) -> 5188.0334 | I28: =H28/G28 -> 0.24819717 | K28: UBS | L28: UBS | M28: =IFERROR((SUMIFS(Bonds!AC:AC,Bonds!B:B,LTV!L28)+ SUMIFS('Bonds ETFs'!S:S,'Bonds ETFs'!A:A,LTV!L28)+ SUMIFS(Deposits!V:V,Deposits!A:A,LTV!L28)+ SUMIFS(Equities!L:L,Equities!A:A,LTV!L28)+ SUMIFS('Alternative assets'!Z:Z,'Alternative assets'!A:A,LTV!L28)+ SUMIFS(Cash!H:H,Cash!A:A,LTV!L28)+ SUMIFS('JPM - DP (3R)'!$J:$J,'JPM - DP (3R)'!$A:$A,LTV!L28)),"")/1000*$N28+$O28 -> 20902.871 | N28: 1 | P28: =-(SUMIFS(Loans!G:G,Loans!A:A,L28)/1000+$Q28) -> 5188.0334 | R28: =P28/M28 -> 0.24819717 | S28: Antrarras portfolio in UBS
B29: Mercury portfolio | C29: =IF(D29="Including",1,0) -> 1 | D29: Including | F29: JPM | G29: =SUMIFS($M$27:$M$30,$K$27:$K$30,F29) -> 25945.878 | H29: =SUMIFS($P$27:$P$30,$K$27:$K$30,F29) -> 8441.1313 | I29: =H29/G29 -> 0.32533612 | K29: JPM | L29: JPM Personal | M29: =IFERROR((SUMIFS(Bonds!AC:AC,Bonds!B:B,LTV!L29)+ SUMIFS('Bonds ETFs'!S:S,'Bonds ETFs'!A:A,LTV!L29)+ SUMIFS(Deposits!V:V,Deposits!A:A,LTV!L29)+ SUMIFS(Equities!L:L,Equities!A:A,LTV!L29)+ SUMIFS('Alternative assets'!Z:Z,'Alternative assets'!A:A,LTV!L29)+ SUMIFS(Cash!H:H,Cash!A:A,LTV!L29)+ SUMIFS('JPM - DP (3R)'!$J:$J,'JPM - DP (3R)'!$A:$A,LTV!L29)),"")/1000*$N29+$O29 -> 10000 | N29: 1 | O29: =Deposits!V2/1000 -> 10000 | P29: =-(SUMIFS(Loans!G:G,Loans!A:A,L29)/1000+$Q29) -> 2735.1775 | Q29: =SUMIFS(Loans!$G:$G,Loans!$B:$B,9867456)/1000 -> -2735.1775 | R29: =P29/M29 -> 0.27351775 | S29: USD Liquidity LVNAV Fund in JPM
B30: US Real Estate | C30: =IF(D30="Including",1,0) -> 1 | D30: Including | F30: Total in USD | G30: =SUM(G27:G29) -> #VALUE! | H30: =SUM(H27:H29) -> 49481.316 | I30: =H30/G30 -> #VALUE! | K30: JPM | L30: JPM | M30: =IFERROR((SUMIFS(Bonds!AC:AC,Bonds!B:B,LTV!L30)+ SUMIFS('Bonds ETFs'!S:S,'Bonds ETFs'!A:A,LTV!L30)+ SUMIFS(Deposits!V:V,Deposits!A:A,LTV!L30)+ SUMIFS(Equities!L:L,Equities!A:A,LTV!L30)+ SUMIFS('Alternative assets'!Z:Z,'Alternative assets'!A:A,LTV!L30)+ SUMIFS(Cash!H:H,Cash!A:A,LTV!L30)+ SUMIFS('JPM - DP (3R)'!$J:$J,'JPM - DP (3R)'!$A:$A,LTV!L30)),"")/1000*$N30+$O30 -> 15945.878 | N30: 1 | O30: =-O29 -> -10000 | P30: =-(SUMIFS(Loans!G:G,Loans!A:A,L30)/1000+$Q30) -> 5705.9537 | Q30: =-Q29 -> 2735.1775 | R30: =P30/M30 -> 0.35783252 | S30: 3R portfolio in JPM
B31: Transfer from 3R to Antarras (V) | D31: 0 | K31: Total in USD | M31: =SUM(M27:M30) -> #VALUE! | P31: =SUM(P27:P30) -> 49481.316 | R31: =P31/M31 -> #VALUE!
B32: New credit line in Vontobel | D32: 0
B33: Currency of New credit line in Vontobel | D33: EUR
B34: Transfer from Vontobel to JPM | D34: 6400 | F34: LTV by banks (All assets) | I34: In tousands of USD | K34: LTV Calculation (All assets) | S34: In tousands of USD
B35: Pay off JPM Personal loans | D35: 3200 | F35: Bank | G35: Market Value | H35: Loans | I35: LTV | K35: Asset class | L35: Bank | M35: Market Value | N35: Assets Adj. 1 | O35: Assets Adj. 2 | P35: Total loans | Q35: Loans Adj. | R35: LTV | S35: Source / Group
B36: Pay off JPM 3R loans | D36: =D34-D35 -> 3200 | F36: Vontobel | G36: =SUMIFS($M$36:$M$47,$L$36:$L$47,F36) -> #VALUE! | H36: =SUMIFS($P$36:$P$47,$L$36:$L$47,F36) -> 35852.151 | I36: =IFERROR(H36/G36,"-") -> - | K36: Personal Portfolio | L36: Vontobel | M36: =IFERROR((SUMIFS(Bonds!AC:AC,Bonds!B:B,LTV!S36)+ SUMIFS('Bonds ETFs'!S:S,'Bonds ETFs'!A:A,LTV!S36)+ SUMIFS(Deposits!V:V,Deposits!A:A,LTV!S36)+ SUMIFS(Equities!L:L,Equities!A:A,LTV!S36)+ SUMIFS('Alternative assets'!Z:Z,'Alternative assets'!A:A,LTV!S36)+ SUMIFS(Cash!H:H,Cash!A:A,LTV!S36))+ SUMIFS('Real Estate'!F:F,'Real Estate'!A:A,S36,'Real Estate'!B:B,LTV!K36)+ SUMIFS('JPM - DP (3R)'!$J:$J,'JPM - DP (3R)'!$A:$A,LTV!S36),"")/1000*$N36+$O36 -> 8419.6917 | N36: 1 | O36: =-O37 -> -10000 | S36: Personal
